Workbook

Sheet Projects Tracker
A1: All Projects — Status Tracker
A2: Project | B2: Done | C2: In Progress / Pending | D2: Backlog / Not Started | E2: Total Tasks | F2: Overall Completion | G2: Status
A3: AI Agents (Mail Digest) | B3: ='AI Agents'!S6 -> 23 | C3: ='AI Agents'!S7 -> 6 | D3: ='AI Agents'!S8 -> 2 | E3: ='AI Agents'!S10 -> 31 | F3: ='AI Agents'!S9 -> 0.82488479 | G3: =IF(F3=1,"Complete",IF(F3>=0.5,"On Track","At Risk")) -> On Track
A4: SG Website | B4: ='SG Website Plan'!O5 -> 28 | C4: ='SG Website Plan'!O6 -> 2 | D4: ='SG Website Plan'!O7 -> 0 | E4: ='SG Website Plan'!O9 -> 30 | F4: ='SG Website Plan'!O8 -> 0.97333333 | G4: =IF(F4=1,"Complete",IF(F4>=0.5,"On Track","At Risk")) -> On Track
A5: Food Safety Program | B5: ='Food Safety Program'!Q2 -> 49 | C5: ='Food Safety Program'!Q3 -> 13 | D5: ='Food Safety Program'!Q4 -> 0 | E5: ='Food Safety Program'!Q6 -> 62 | F5: ='Food Safety Program'!Q5 -> 0.8891129 | G5: =IF(F5=1,"Complete",IF(F5>=0.5,"On Track","At Risk")) -> On Track
A6: C-SAT Survey | B6: ='C-SAT Survey'!P2 -> 57 | C6: ='C-SAT Survey'!P3 -> 0 | D6: ='C-SAT Survey'!P4 -> 8 | E6: ='C-SAT Survey'!P6 -> 65 | F6: ='C-SAT Survey'!P5 -> 0.87692308 | G6: =IF(F6=1,"Complete",IF(F6>=0.5,"On Track","At Risk")) -> On Track
A7: GPM&I Project | B7: ='GPM&I'!P2 -> 0 | C7: ='GPM&I'!P3 -> 77 | D7: ='GPM&I'!P4 -> 42 | E7: ='GPM&I'!P6 -> 119 | F7: ='GPM&I'!P5 -> 0.43137255 | G7: =IF(F7=1,"Complete",IF(F7>=0.5,"On Track","At Risk")) -> At Risk
A8: Trio Academy (LMS) Development | B8: ='Trio Academy(LMS)'!N2 -> 159 | C8: ='Trio Academy(LMS)'!N3 -> 2 | D8: ='Trio Academy(LMS)'!N4 -> 0 | E8: ='Trio Academy(LMS)'!N6 -> 161 | F8: ='Trio Academy(LMS)'!N5 -> 0.99378882 | G8: =IF(F8=1,"Complete",IF(F8>=0.5,"On Track","At Risk")) -> On Track
A9: TOTAL / OVERALL | B9: =SUM(B3:B8) -> 316 | C9: =SUM(C3:C8) -> 100 | D9: =SUM(D3:D8) -> 52 | E9: =SUM(E3:E8) -> 468 | F9: =AVERAGE(F3:F8) -> 0.83156925

Sheet Daily Progress
A1: DAILY PROGRESS DASHBOARD — ALL PROJECTS | M1: 14-DAY ROLLING WORKLOAD LOG
M2: Date | N2: Weekday | O2: Starting | P2: Due | Q2: Active | R2: Overdue Open
A3: Report Date | B3: =TODAY() -> 46275 | D3: Weekday | E3: =TEXT($B$3,"dddd") -> Thursday | M3: =$B$3-6 -> 46269 | N3: =TEXT($M3,"ddd") -> Fri | O3: =COUNTIFS('AI Agents'!$D$5:$D$36,$M3,'AI Agents'!$B$5:$B$36,"<>")+COUNTIFS('SG Website Plan'!$D$4:$D$41,$M3,'SG Website Plan'!$B$4:$B$41,"<>")+COUNTIFS('Food Safety Program'!$D$4:$D$69,$M3,'Food Safety Program'!$B$4:$B$69,"<>")+COUNTIFS('C-SAT Survey'!$D$4:$D$75,$M3,'C-SAT Survey'!$B$4:$B$75,"<>")+COUNTIFS('GPM&I'!$E$4:$E$115,$M3,'GPM&I'!$C$4:$C$115,"<>")+COUNTIFS('Trio Academy(LMS)'!$D$4:$D$164,$M3,'Trio Academy(LMS)'!$B$4:$B$164,"<>") -> 0 | P3: =COUNTIFS('AI Agents'!$E$5:$E$36,$M3,'AI Agents'!$B$5:$B$36,"<>")+COUNTIFS('SG Website Plan'!$E$4:$E$41,$M3,'SG Website Plan'!$B$4:$B$41,"<>")+COUNTIFS('Food Safety Program'!$E$4:$E$69,$M3,'Food Safety Program'!$B$4:$B$69,"<>")+COUNTIFS('C-SAT Survey'!$E$4:$E$75,$M3,'C-SAT Survey'!$B$4:$B$75,"<>")+COUNTIFS('GPM&I'!$F$4:$F$115,$M3,'GPM&I'!$C$4:$C$115,"<>")+COUNTIFS('Trio Academy(LMS)'!$E$4:$E$164,$M3,'Trio Academy(LMS)'!$B$4:$B$164,"<>") -> 0 | Q3: =COUNTIFS('AI Agents'!$D$5:$D$36,">0",'AI Agents'!$D$5:$D$36,"<="&$M3,'AI Agents'!$E$5:$E$36,">="&$M3,'AI Agents'!$B$5:$B$36,"<>")+COUNTIFS('SG Website Plan'!$D$4:$D$41,">0",'SG Website Plan'!$D$4:$D$41,"<="&$M3,'SG Website Plan'!$E$4:$E$41,">="&$M3,'SG Website Plan'!$B$4:$B$41,"<>")+COUNTIFS('Food Safety Program'!$D$4:$D$69,">0",'Food Safety Program'!$D$4:$D$69,"<="&$M3,'Food Safety Program'!$E$4:$E$69,">="&$M3,'Food Safety Program'!$B$4:$B$69,"<>")+COUNTIFS('C-SAT Survey'!$D$4:$D$75,">0",'C-SAT Survey'!$D$4:$D$75,"<="&$M3,'C-SAT Survey'!$E$4:$E$75,">="&$M3,'C-SAT Survey'!$B$4:$B$75,"<>")+COUNTIFS('GPM&I'!$E$4:$E$115,">0",'GPM&I'!$E$4:$E$115,"<="&$M3,'GPM&I'!$F$4:$F$115,">="&$M3,'GPM&I'!$C$4:$C$115,"<>")+COUNTIFS('Trio Academy(LMS)'!$D$4:$D$164,">0",'Trio Academy(LMS)'!$D$4:$D$164,"<="&$M3,'Trio Academy(LMS)'!$E$4:$E$164,">="&$M3,'Trio Academy(LMS)'!$B$4:$B$164,"<>") -> 58 | R3: =COUNTIFS('AI Agents'!$E$5:$E$36,"<"&$M3,'AI Agents'!$E$5:$E$36,">0",'AI Agents'!$N$5:$N$36,"<1")+COUNTIFS('SG Website Plan'!$E$4:$E$41,"<"&$M3,'SG Website Plan'!$E$4:$E$41,">0",'SG Website Plan'!$L$4:$L$41,"<1")+COUNTIFS('Food Safety Program'!$E$4:$E$69,"<"&$M3,'Food Safety Program'!$E$4:$E$69,">0",'Food Safety Program'!$O$4:$O$69,"<1")+COUNTIFS('C-SAT Survey'!$E$4:$E$75,"<"&$M3,'C-SAT Survey'!$E$4:$E$75,">0",'C-SAT Survey'!$M$4:$M$75,"<1")+COUNTIFS('GPM&I'!$F$4:$F$115,"<"&$M3,'GPM&I'!$F$4:$F$115,">0",'GPM&I'!$M$4:$M$115,"<1")+COUNTIFS('Trio Academy(LMS)'!$E$4:$E$164,"<"&$M3,'Trio Academy(LMS)'!$E$4:$E$164,">0",'Trio Academy(LMS)'!$L$4:$L$164,"<1") -> 20
A4: Portfolio Completion | B4: ='Projects Tracker'!F9 -> 0.83156925 | D4: Total Tasks | E4: ='Projects Tracker'!E9 -> 468 | M4: =M3+1 -> 46270 | N4: =TEXT($M4,"ddd") -> Sat | O4: =COUNTIFS('AI Agents'!$D$5:$D$36,$M4,'AI Agents'!$B$5:$B$36,"<>")+COUNTIFS('SG Website Plan'!$D$4:$D$41,$M4,'SG Website Plan'!$B$4:$B$41,"<>")+COUNTIFS('Food Safety Program'!$D$4:$D$69,$M4,'Food Safety Program'!$B$4:$B$69,"<>")+COUNTIFS('C-SAT Survey'!$D$4:$D$75,$M4,'C-SAT Survey'!$B$4:$B$75,"<>")+COUNTIFS('GPM&I'!$E$4:$E$115,$M4,'GPM&I'!$C$4:$C$115,"<>")+COUNTIFS('Trio Academy(LMS)'!$D$4:$D$164,$M4,'Trio Academy(LMS)'!$B$4:$B$164,"<>") -> 0 | P4: =COUNTIFS('AI Agents'!$E$5:$E$36,$M4,'AI Agents'!$B$5:$B$36,"<>")+COUNTIFS('SG Website Plan'!$E$4:$E$41,$M4,'SG Website Plan'!$B$4:$B$41,"<>")+COUNTIFS('Food Safety Program'!$E$4:$E$69,$M4,'Food Safety Program'!$B$4:$B$69,"<>")+COUNTIFS('C-SAT Survey'!$E$4:$E$75,$M4,'C-SAT Survey'!$B$4:$B$75,"<>")+COUNTIFS('GPM&I'!$F$4:$F$115,$M4,'GPM&I'!$C$4:$C$115,"<>")+COUNTIFS('Trio Academy(LMS)'!$E$4:$E$164,$M4,'Trio Academy(LMS)'!$B$4:$B$164,"<>") -> 16 | Q4: =COUNTIFS('AI Agents'!$D$5:$D$36,">0",'AI Agents'!$D$5:$D$36,"<="&$M4,'AI Agents'!$E$5:$E$36,">="&$M4,'AI Agents'!$B$5:$B$36,"<>")+COUNTIFS('SG Website Plan'!$D$4:$D$41,">0",'SG Website Plan'!$D$4:$D$41,"<="&$M4,'SG Website Plan'!$E$4:$E$41,">="&$M4,'SG Website Plan'!$B$4:$B$41,"<>")+COUNTIFS('Food Safety Program'!$D$4:$D$69,">0",'Food Safety Program'!$D$4:$D$69,"<="&$M4,'Food Safety Program'!$E$4:$E$69,">="&$M4,'Food Safety Program'!$B$4:$B$69,"<>")+COUNTIFS('C-SAT Survey'!$D$4:$D$75,">0",'C-SAT Survey'!$D$4:$D$75,"<="&$M4,'C-SAT Survey'!$E$4:$E$75,">="&$M4,'C-SAT Survey'!$B$4:$B$75,"<>")+COUNTIFS('GPM&I'!$E$4:$E$115,">0",'GPM&I'!$E$4:$E$115,"<="&$M4,'GPM&I'!$F$4:$F$115,">="&$M4,'GPM&I'!$C$4:$C$115,"<>")+COUNTIFS('Trio Academy(LMS)'!$D$4:$D$164,">0",'Trio Academy(LMS)'!$D$4:$D$164,"<="&$M4,'Trio Academy(LMS)'!$E$4:$E$164,">="&$M4,'Trio Academy(LMS)'!$B$4:$B$164,"<>") -> 58 | R4: =COUNTIFS('AI Agents'!$E$5:$E$36,"<"&$M4,'AI Agents'!$E$5:$E$36,">0",'AI Agents'!$N$5:$N$36,"<1")+COUNTIFS('SG Website Plan'!$E$4:$E$41,"<"&$M4,'SG Website Plan'!$E$4:$E$41,">0",'SG Website Plan'!$L$4:$L$41,"<1")+COUNTIFS('Food Safety Program'!$E$4:$E$69,"<"&$M4,'Food Safety Program'!$E$4:$E$69,">0",'Food Safety Program'!$O$4:$O$69,"<1")+COUNTIFS('C-SAT Survey'!$E$4:$E$75,"<"&$M4,'C-SAT Survey'!$E$4:$E$75,">0",'C-SAT Survey'!$M$4:$M$75,"<1")+COUNTIFS('GPM&I'!$F$4:$F$115,"<"&$M4,'GPM&I'!$F$4:$F$115,">0",'GPM&I'!$M$4:$M$115,"<1")+COUNTIFS('Trio Academy(LMS)'!$E$4:$E$164,"<"&$M4,'Trio Academy(LMS)'!$E$4:$E$164,">0",'Trio Academy(LMS)'!$L$4:$L$164,"<1") -> 20
M5: =M4+1 -> 46271 | N5: =TEXT($M5,"ddd") -> Sun | O5: =COUNTIFS('AI Agents'!$D$5:$D$36,$M5,'AI Agents'!$B$5:$B$36,"<>")+COUNTIFS('SG Website Plan'!$D$4:$D$41,$M5,'SG Website Plan'!$B$4:$B$41,"<>")+COUNTIFS('Food Safety Program'!$D$4:$D$69,$M5,'Food Safety Program'!$B$4:$B$69,"<>")+COUNTIFS('C-SAT Survey'!$D$4:$D$75,$M5,'C-SAT Survey'!$B$4:$B$75,"<>")+COUNTIFS('GPM&I'!$E$4:$E$115,$M5,'GPM&I'!$C$4:$C$115,"<>")+COUNTIFS('Trio Academy(LMS)'!$D$4:$D$164,$M5,'Trio Academy(LMS)'!$B$4:$B$164,"<>") -> 6 | P5: =COUNTIFS('AI Agents'!$E$5:$E$36,$M5,'AI Agents'!$B$5:$B$36,"<>")+COUNTIFS('SG Website Plan'!$E$4:$E$41,$M5,'SG Website Plan'!$B$4:$B$41,"<>")+COUNTIFS('Food Safety Program'!$E$4:$E$69,$M5,'Food Safety Program'!$B$4:$B$69,"<>")+COUNTIFS('C-SAT Survey'!$E$4:$E$75,$M5,'C-SAT Survey'!$B$4:$B$75,"<>")+COUNTIFS('GPM&I'!$F$4:$F$115,$M5,'GPM&I'!$C$4:$C$115,"<>")+COUNTIFS('Trio Academy(LMS)'!$E$4:$E$164,$M5,'Trio Academy(LMS)'!$B$4:$B$164,"<>") -> 2 | Q5: =COUNTIFS('AI Agents'!$D$5:$D$36,">0",'AI Agents'!$D$5:$D$36,"<="&$M5,'AI Agents'!$E$5:$E$36,">="&$M5,'AI Agents'!$B$5:$B$36,"<>")+COUNTIFS('SG Website Plan'!$D$4:$D$41,">0",'SG Website Plan'!$D$4:$D$41,"<="&$M5,'SG Website Plan'!$E$4:$E$41,">="&$M5,'SG Website Plan'!$B$4:$B$41,"<>")+COUNTIFS('Food Safety Program'!$D$4:$D$69,">0",'Food Safety Program'!$D$4:$D$69,"<="&$M5,'Food Safety Program'!$E$4:$E$69,">="&$M5,'Food Safety Program'!$B$4:$B$69,"<>")+COUNTIFS('C-SAT Survey'!$D$4:$D$75,">0",'C-SAT Survey'!$D$4:$D$75,"<="&$M5,'C-SAT Survey'!$E$4:$E$75,">="&$M5,'C-SAT Survey'!$B$4:$B$75,"<>")+COUNTIFS('GPM&I'!$E$4:$E$115,">0",'GPM&I'!$E$4:$E$115,"<="&$M5,'GPM&I'!$F$4:$F$115,">="&$M5,'GPM&I'!$C$4:$C$115,"<>")+COUNTIFS('Trio Academy(LMS)'!$D$4:$D$164,">0",'Trio Academy(LMS)'!$D$4:$D$164,"<="&$M5,'Trio Academy(LMS)'!$E$4:$E$164,">="&$M5,'Trio Academy(LMS)'!$B$4:$B$164,"<>") -> 48 | R5: =COUNTIFS('AI Agents'!$E$5:$E$36,"<"&$M5,'AI Agents'!$E$5:$E$36,">0",'AI Agents'!$N$5:$N$36,"<1")+COUNTIFS('SG Website Plan'!$E$4:$E$41,"<"&$M5,'SG Website Plan'!$E$4:$E$41,">0",'SG Website Plan'!$L$4:$L$41,"<1")+COUNTIFS('Food Safety Program'!$E$4:$E$69,"<"&$M5,'Food Safety Program'!$E$4:$E$69,">0",'Food Safety Program'!$O$4:$O$69,"<1")+COUNTIFS('C-SAT Survey'!$E$4:$E$75,"<"&$M5,'C-SAT Survey'!$E$4:$E$75,">0",'C-SAT Survey'!$M$4:$M$75,"<1")+COUNTIFS('GPM&I'!$F$4:$F$115,"<"&$M5,'GPM&I'!$F$4:$F$115,">0",'GPM&I'!$M$4:$M$115,"<1")+COUNTIFS('Trio Academy(LMS)'!$E$4:$E$164,"<"&$M5,'Trio Academy(LMS)'!$E$4:$E$164,">0",'Trio Academy(LMS)'!$L$4:$L$164,"<1") -> 27
A6: PROJECT ROLLUP FOR REPORT DATE | M6: =M5+1 -> 46272 | N6: =TEXT($M6,"ddd") -> Mon | O6: =COUNTIFS('AI Agents'!$D$5:$D$36,$M6,'AI Agents'!$B$5:$B$36,"<>")+COUNTIFS('SG Website Plan'!$D$4:$D$41,$M6,'SG Website Plan'!$B$4:$B$41,"<>")+COUNTIFS('Food Safety Program'!$D$4:$D$69,$M6,'Food Safety Program'!$B$4:$B$69,"<>")+COUNTIFS('C-SAT Survey'!$D$4:$D$75,$M6,'C-SAT Survey'!$B$4:$B$75,"<>")+COUNTIFS('GPM&I'!$E$4:$E$115,$M6,'GPM&I'!$C$4:$C$115,"<>")+COUNTIFS('Trio Academy(LMS)'!$D$4:$D$164,$M6,'Trio Academy(LMS)'!$B$4:$B$164,"<>") -> 3 | P6: =COUNTIFS('AI Agents'!$E$5:$E$36,$M6,'AI Agents'!$B$5:$B$36,"<>")+COUNTIFS('SG Website Plan'!$E$4:$E$41,$M6,'SG Website Plan'!$B$4:$B$41,"<>")+COUNTIFS('Food Safety Program'!$E$4:$E$69,$M6,'Food Safety Program'!$B$4:$B$69,"<>")+COUNTIFS('C-SAT Survey'!$E$4:$E$75,$M6,'C-SAT Survey'!$B$4:$B$75,"<>")+COUNTIFS('GPM&I'!$F$4:$F$115,$M6,'GPM&I'!$C$4:$C$115,"<>")+COUNTIFS('Trio Academy(LMS)'!$E$4:$E$164,$M6,'Trio Academy(LMS)'!$B$4:$B$164,"<>") -> 6 | Q6: =COUNTIFS('AI Agents'!$D$5:$D$36,">0",'AI Agents'!$D$5:$D$36,"<="&$M6,'AI Agents'!$E$5:$E$36,">="&$M6,'AI Agents'!$B$5:$B$36,"<>")+COUNTIFS('SG Website Plan'!$D$4:$D$41,">0",'SG Website Plan'!$D$4:$D$41,"<="&$M6,'SG Website Plan'!$E$4:$E$41,">="&$M6,'SG Website Plan'!$B$4:$B$41,"<>")+COUNTIFS('Food Safety Program'!$D$4:$D$69,">0",'Food Safety Program'!$D$4:$D$69,"<="&$M6,'Food Safety Program'!$E$4:$E$69,">="&$M6,'Food Safety Program'!$B$4:$B$69,"<>")+COUNTIFS('C-SAT Survey'!$D$4:$D$75,">0",'C-SAT Survey'!$D$4:$D$75,"<="&$M6,'C-SAT Survey'!$E$4:$E$75,">="&$M6,'C-SAT Survey'!$B$4:$B$75,"<>")+COUNTIFS('GPM&I'!$E$4:$E$115,">0",'GPM&I'!$E$4:$E$115,"<="&$M6,'GPM&I'!$F$4:$F$115,">="&$M6,'GPM&I'!$C$4:$C$115,"<>")+COUNTIFS('Trio Academy(LMS)'!$D$4:$D$164,">0",'Trio Academy(LMS)'!$D$4:$D$164,"<="&$M6,'Trio Academy(LMS)'!$E$4:$E$164,">="&$M6,'Trio Academy(LMS)'!$B$4:$B$164,"<>") -> 49 | R6: =COUNTIFS('AI Agents'!$E$5:$E$36,"<"&$M6,'AI Agents'!$E$5:$E$36,">0",'AI Agents'!$N$5:$N$36,"<1")+COUNTIFS('SG Website Plan'!$E$4:$E$41,"<"&$M6,'SG Website Plan'!$E$4:$E$41,">0",'SG Website Plan'!$L$4:$L$41,"<1")+COUNTIFS('Food Safety Program'!$E$4:$E$69,"<"&$M6,'Food Safety Program'!$E$4:$E$69,">0",'Food Safety Program'!$O$4:$O$69,"<1")+COUNTIFS('C-SAT Survey'!$E$4:$E$75,"<"&$M6,'C-SAT Survey'!$E$4:$E$75,">0",'C-SAT Survey'!$M$4:$M$75,"<1")+COUNTIFS('GPM&I'!$F$4:$F$115,"<"&$M6,'GPM&I'!$F$4:$F$115,">0",'GPM&I'!$M$4:$M$115,"<1")+COUNTIFS('Trio Academy(LMS)'!$E$4:$E$164,"<"&$M6,'Trio Academy(LMS)'!$E$4:$E$164,">0",'Trio Academy(LMS)'!$L$4:$L$164,"<1") -> 29
A7: Project | B7: Starting Today | C7: Due Today | D7: Active Today | E7: Overdue Open | F7: Done | G7: In Progress | H7: Not Started | I7: Total Tasks | J7: Completion % | K7: Status | M7: =M6+1 -> 46273 | N7: =TEXT($M7,"ddd") -> Tue | O7: =COUNTIFS('AI Agents'!$D$5:$D$36,$M7,'AI Agents'!$B$5:$B$36,"<>")+COUNTIFS('SG Website Plan'!$D$4:$D$41,$M7,'SG Website Plan'!$B$4:$B$41,"<>")+COUNTIFS('Food Safety Program'!$D$4:$D$69,$M7,'Food Safety Program'!$B$4:$B$69,"<>")+COUNTIFS('C-SAT Survey'!$D$4:$D$75,$M7,'C-SAT Survey'!$B$4:$B$75,"<>")+COUNTIFS('GPM&I'!$E$4:$E$115,$M7,'GPM&I'!$C$4:$C$115,"<>")+COUNTIFS('Trio Academy(LMS)'!$D$4:$D$164,$M7,'Trio Academy(LMS)'!$B$4:$B$164,"<>") -> 2 | P7: =COUNTIFS('AI Agents'!$E$5:$E$36,$M7,'AI Agents'!$B$5:$B$36,"<>")+COUNTIFS('SG Website Plan'!$E$4:$E$41,$M7,'SG Website Plan'!$B$4:$B$41,"<>")+COUNTIFS('Food Safety Program'!$E$4:$E$69,$M7,'Food Safety Program'!$B$4:$B$69,"<>")+COUNTIFS('C-SAT Survey'!$E$4:$E$75,$M7,'C-SAT Survey'!$B$4:$B$75,"<>")+COUNTIFS('GPM&I'!$F$4:$F$115,$M7,'GPM&I'!$C$4:$C$115,"<>")+COUNTIFS('Trio Academy(LMS)'!$E$4:$E$164,$M7,'Trio Academy(LMS)'!$B$4:$B$164,"<>") -> 2 | Q7: =COUNTIFS('AI Agents'!$D$5:$D$36,">0",'AI Agents'!$D$5:$D$36,"<="&$M7,'AI Agents'!$E$5:$E$36,">="&$M7,'AI Agents'!$B$5:$B$36,"<>")+COUNTIFS('SG Website Plan'!$D$4:$D$41,">0",'SG Website Plan'!$D$4:$D$41,"<="&$M7,'SG Website Plan'!$E$4:$E$41,">="&$M7,'SG Website Plan'!$B$4:$B$41,"<>")+COUNTIFS('Food Safety Program'!$D$4:$D$69,">0",'Food Safety Program'!$D$4:$D$69,"<="&$M7,'Food Safety Program'!$E$4:$E$69,">="&$M7,'Food Safety Program'!$B$4:$B$69,"<>")+COUNTIFS('C-SAT Survey'!$D$4:$D$75,">0",'C-SAT Survey'!$D$4:$D$75,"<="&$M7,'C-SAT Survey'!$E$4:$E$75,">="&$M7,'C-SAT Survey'!$B$4:$B$75,"<>")+COUNTIFS('GPM&I'!$E$4:$E$115,">0",'GPM&I'!$E$4:$E$115,"<="&$M7,'GPM&I'!$F$4:$F$115,">="&$M7,'GPM&I'!$C$4:$C$115,"<>")+COUNTIFS('Trio Academy(LMS)'!$D$4:$D$164,">0",'Trio Academy(LMS)'!$D$4:$D$164,"<="&$M7,'Trio Academy(LMS)'!$E$4:$E$164,">="&$M7,'Trio Academy(LMS)'!$B$4:$B$164,"<>") -> 45 | R7: =COUNTIFS('AI Agents'!$E$5:$E$36,"<"&$M7,'AI Agents'!$E$5:$E$36,">0",'AI Agents'!$N$5:$N$36,"<1")+COUNTIFS('SG Website Plan'!$E$4:$E$41,"<"&$M7,'SG Website Plan'!$E$4:$E$41,">0",'SG Website Plan'!$L$4:$L$41,"<1")+COUNTIFS('Food Safety Program'!$E$4:$E$69,"<"&$M7,'Food Safety Program'!$E$4:$E$69,">0",'Food Safety Program'!$O$4:$O$69,"<1")+COUNTIFS('C-SAT Survey'!$E$4:$E$75,"<"&$M7,'C-SAT Survey'!$E$4:$E$75,">0",'C-SAT Survey'!$M$4:$M$75,"<1")+COUNTIFS('GPM&I'!$F$4:$F$115,"<"&$M7,'GPM&I'!$F$4:$F$115,">0",'GPM&I'!$M$4:$M$115,"<1")+COUNTIFS('Trio Academy(LMS)'!$E$4:$E$164,"<"&$M7,'Trio Academy(LMS)'!$E$4:$E$164,">0",'Trio Academy(LMS)'!$L$4:$L$164,"<1") -> 31
A8: AI Agents (Mail Digest) | B8: =COUNTIFS('AI Agents'!$D$5:$D$36,$B$3,'AI Agents'!$B$5:$B$36,"<>") -> 0 | C8: =COUNTIFS('AI Agents'!$E$5:$E$36,$B$3,'AI Agents'!$B$5:$B$36,"<>") -> 0 | D8: =COUNTIFS('AI Agents'!$D$5:$D$36,">0",'AI Agents'!$D$5:$D$36,"<="&$B$3,'AI Agents'!$E$5:$E$36,">="&$B$3,'AI Agents'!$B$5:$B$36,"<>") -> 0 | E8: =COUNTIFS('AI Agents'!$E$5:$E$36,"<"&$B$3,'AI Agents'!$E$5:$E$36,">0",'AI Agents'!$N$5:$N$36,"<1") -> 8 | F8: =COUNTIFS('AI Agents'!$N$5:$N$36,1) -> 23 | G8: =COUNTIFS('AI Agents'!$N$5:$N$36,">0",'AI Agents'!$N$5:$N$36,"<1") -> 6 | H8: =COUNTIFS('AI Agents'!$N$5:$N$36,0) -> 2 | I8: =COUNT('AI Agents'!$N$5:$N$36) -> 31 | J8: =IFERROR(AVERAGE('AI Agents'!$N$5:$N$36),0) -> 0.82488479 | K8: =IF(J8=1,"Complete",IF(J8>=0.5,"On Track",IF(J8>0,"At Risk","Not Started"))) -> On Track | M8: =#REF!+1 -> #REF! | N8: =TEXT($M8,"ddd") -> #REF! | O8: =COUNTIFS('AI Agents'!$D$5:$D$36,$M8,'AI Agents'!$B$5:$B$36,"<>")+COUNTIFS('SG Website Plan'!$D$4:$D$41,$M8,'SG Website Plan'!$B$4:$B$41,"<>")+COUNTIFS('Food Safety Program'!$D$4:$D$69,$M8,'Food Safety Program'!$B$4:$B$69,"<>")+COUNTIFS('C-SAT Survey'!$D$4:$D$75,$M8,'C-SAT Survey'!$B$4:$B$75,"<>")+COUNTIFS('GPM&I'!$E$4:$E$115,$M8,'GPM&I'!$C$4:$C$115,"<>")+COUNTIFS('Trio Academy(LMS)'!$D$4:$D$164,$M8,'Trio Academy(LMS)'!$B$4:$B$164,"<>") -> 0 | P8: =COUNTIFS('AI Agents'!$E$5:$E$36,$M8,'AI Agents'!$B$5:$B$36,"<>")+COUNTIFS('SG Website Plan'!$E$4:$E$41,$M8,'SG Website Plan'!$B$4:$B$41,"<>")+COUNTIFS('Food Safety Program'!$E$4:$E$69,$M8,'Food Safety Program'!$B$4:$B$69,"<>")+COUNTIFS('C-SAT Survey'!$E$4:$E$75,$M8,'C-SAT Survey'!$B$4:$B$75,"<>")+COUNTIFS('GPM&I'!$F$4:$F$115,$M8,'GPM&I'!$C$4:$C$115,"<>")+COUNTIFS('Trio Academy(LMS)'!$E$4:$E$164,$M8,'Trio Academy(LMS)'!$B$4:$B$164,"<>") -> 0 | Q8: =COUNTIFS('AI Agents'!$D$5:$D$36,">0",'AI Agents'!$D$5:$D$36,"<="&$M8,'AI Agents'!$E$5:$E$36,">="&$M8,'AI Agents'!$B$5:$B$36,"<>")+COUNTIFS('SG Website Plan'!$D$4:$D$41,">0",'SG Website Plan'!$D$4:$D$41,"<="&$M8,'SG Website Plan'!$E$4:$E$41,">="&$M8,'SG Website Plan'!$B$4:$B$41,"<>")+COUNTIFS('Food Safety Program'!$D$4:$D$69,">0",'Food Safety Program'!$D$4:$D$69,"<="&$M8,'Food Safety Program'!$E$4:$E$69,">="&$M8,'Food Safety Program'!$B$4:$B$69,"<>")+COUNTIFS('C-SAT Survey'!$D$4:$D$75,">0",'C-SAT Survey'!$D$4:$D$75,"<="&$M8,'C-SAT Survey'!$E$4:$E$75,">="&$M8,'C-SAT Survey'!$B$4:$B$75,"<>")+COUNTIFS('GPM&I'!$E$4:$E$115,">0",'GPM&I'!$E$4:$E$115,"<="&$M8,'GPM&I'!$F$4:$F$115,">="&$M8,'GPM&I'!$C$4:$C$115,"<>")+COUNTIFS('Trio Academy(LMS)'!$D$4:$D$164,">0",'Trio Academy(LMS)'!$D$4:$D$164,"<="&$M8,'Trio Academy(LMS)'!$E$4:$E$164,">="&$M8,'Trio Academy(LMS)'!$B$4:$B$164,"<>") -> 0 | R8: =COUNTIFS('AI Agents'!$E$5:$E$36,"<"&$M8,'AI Agents'!$E$5:$E$36,">0",'AI Agents'!$N$5:$N$36,"<1")+COUNTIFS('SG Website Plan'!$E$4:$E$41,"<"&$M8,'SG Website Plan'!$E$4:$E$41,">0",'SG Website Plan'!$L$4:$L$41,"<1")+COUNTIFS('Food Safety Program'!$E$4:$E$69,"<"&$M8,'Food Safety Program'!$E$4:$E$69,">0",'Food Safety Program'!$O$4:$O$69,"<1")+COUNTIFS('C-SAT Survey'!$E$4:$E$75,"<"&$M8,'C-SAT Survey'!$E$4:$E$75,">0",'C-SAT Survey'!$M$4:$M$75,"<1")+COUNTIFS('GPM&I'!$F$4:$F$115,"<"&$M8,'GPM&I'!$F$4:$F$115,">0",'GPM&I'!$M$4:$M$115,"<1")+COUNTIFS('Trio Academy(LMS)'!$E$4:$E$164,"<"&$M8,'Trio Academy(LMS)'!$E$4:$E$164,">0",'Trio Academy(LMS)'!$L$4:$L$164,"<1") -> 0
A9: SG Website Plan | B9: =COUNTIFS('SG Website Plan'!$D$4:$D$41,$B$3,'SG Website Plan'!$B$4:$B$41,"<>") -> 0 | C9: =COUNTIFS('SG Website Plan'!$E$4:$E$41,$B$3,'SG Website Plan'!$B$4:$B$41,"<>") -> 0 | D9: =COUNTIFS('SG Website Plan'!$D$4:$D$41,">0",'SG Website Plan'!$D$4:$D$41,"<="&$B$3,'SG Website Plan'!$E$4:$E$41,">="&$B$3,'SG Website Plan'!$B$4:$B$41,"<>") -> 0 | E9: =COUNTIFS('SG Website Plan'!$E$4:$E$41,"<"&$B$3,'SG Website Plan'!$E$4:$E$41,">0",'SG Website Plan'!$L$4:$L$41,"<1") -> 2 | F9: =COUNTIFS('SG Website Plan'!$L$4:$L$41,1) -> 28 | G9: =COUNTIFS('SG Website Plan'!$L$4:$L$41,">0",'SG Website Plan'!$L$4:$L$41,"<1") -> 2 | H9: =COUNTIFS('SG Website Plan'!$L$4:$L$41,0) -> 0 | I9: =COUNT('SG Website Plan'!$L$4:$L$41) -> 30 | J9: =IFERROR(AVERAGE('SG Website Plan'!$L$4:$L$41),0) -> 0.97333333 | K9: =IF(J9=1,"Complete",IF(J9>=0.5,"On Track",IF(J9>0,"At Risk","Not Started"))) -> On Track | M9: =M8+1 -> #REF! | N9: =TEXT($M9,"ddd") -> #REF! | O9: =COUNTIFS('AI Agents'!$D$5:$D$36,$M9,'AI Agents'!$B$5:$B$36,"<>")+COUNTIFS('SG Website Plan'!$D$4:$D$41,$M9,'SG Website Plan'!$B$4:$B$41,"<>")+COUNTIFS('Food Safety Program'!$D$4:$D$69,$M9,'Food Safety Program'!$B$4:$B$69,"<>")+COUNTIFS('C-SAT Survey'!$D$4:$D$75,$M9,'C-SAT Survey'!$B$4:$B$75,"<>")+COUNTIFS('GPM&I'!$E$4:$E$115,$M9,'GPM&I'!$C$4:$C$115,"<>")+COUNTIFS('Trio Academy(LMS)'!$D$4:$D$164,$M9,'Trio Academy(LMS)'!$B$4:$B$164,"<>") -> 0 | P9: =COUNTIFS('AI Agents'!$E$5:$E$36,$M9,'AI Agents'!$B$5:$B$36,"<>")+COUNTIFS('SG Website Plan'!$E$4:$E$41,$M9,'SG Website Plan'!$B$4:$B$41,"<>")+COUNTIFS('Food Safety Program'!$E$4:$E$69,$M9,'Food Safety Program'!$B$4:$B$69,"<>")+COUNTIFS('C-SAT Survey'!$E$4:$E$75,$M9,'C-SAT Survey'!$B$4:$B$75,"<>")+COUNTIFS('GPM&I'!$F$4:$F$115,$M9,'GPM&I'!$C$4:$C$115,"<>")+COUNTIFS('Trio Academy(LMS)'!$E$4:$E$164,$M9,'Trio Academy(LMS)'!$B$4:$B$164,"<>") -> 0 | Q9: =COUNTIFS('AI Agents'!$D$5:$D$36,">0",'AI Agents'!$D$5:$D$36,"<="&$M9,'AI Agents'!$E$5:$E$36,">="&$M9,'AI Agents'!$B$5:$B$36,"<>")+COUNTIFS('SG Website Plan'!$D$4:$D$41,">0",'SG Website Plan'!$D$4:$D$41,"<="&$M9,'SG Website Plan'!$E$4:$E$41,">="&$M9,'SG Website Plan'!$B$4:$B$41,"<>")+COUNTIFS('Food Safety Program'!$D$4:$D$69,">0",'Food Safety Program'!$D$4:$D$69,"<="&$M9,'Food Safety Program'!$E$4:$E$69,">="&$M9,'Food Safety Program'!$B$4:$B$69,"<>")+COUNTIFS('C-SAT Survey'!$D$4:$D$75,">0",'C-SAT Survey'!$D$4:$D$75,"<="&$M9,'C-SAT Survey'!$E$4:$E$75,">="&$M9,'C-SAT Survey'!$B$4:$B$75,"<>")+COUNTIFS('GPM&I'!$E$4:$E$115,">0",'GPM&I'!$E$4:$E$115,"<="&$M9,'GPM&I'!$F$4:$F$115,">="&$M9,'GPM&I'!$C$4:$C$115,"<>")+COUNTIFS('Trio Academy(LMS)'!$D$4:$D$164,">0",'Trio Academy(LMS)'!$D$4:$D$164,"<="&$M9,'Trio Academy(LMS)'!$E$4:$E$164,">="&$M9,'Trio Academy(LMS)'!$B$4:$B$164,"<>") -> 0 | R9: =COUNTIFS('AI Agents'!$E$5:$E$36,"<"&$M9,'AI Agents'!$E$5:$E$36,">0",'AI Agents'!$N$5:$N$36,"<1")+COUNTIFS('SG Website Plan'!$E$4:$E$41,"<"&$M9,'SG Website Plan'!$E$4:$E$41,">0",'SG Website Plan'!$L$4:$L$41,"<1")+COUNTIFS('Food Safety Program'!$E$4:$E$69,"<"&$M9,'Food Safety Program'!$E$4:$E$69,">0",'Food Safety Program'!$O$4:$O$69,"<1")+COUNTIFS('C-SAT Survey'!$E$4:$E$75,"<"&$M9,'C-SAT Survey'!$E$4:$E$75,">0",'C-SAT Survey'!$M$4:$M$75,"<1")+COUNTIFS('GPM&I'!$F$4:$F$115,"<"&$M9,'GPM&I'!$F$4:$F$115,">0",'GPM&I'!$M$4:$M$115,"<1")+COUNTIFS('Trio Academy(LMS)'!$E$4:$E$164,"<"&$M9,'Trio Academy(LMS)'!$E$4:$E$164,">0",'Trio Academy(LMS)'!$L$4:$L$164,"<1") -> 0
A10: Food Safety Program | B10: =COUNTIFS('Food Safety Program'!$D$4:$D$69,$B$3,'Food Safety Program'!$B$4:$B$69,"<>") -> 0 | C10: =COUNTIFS('Food Safety Program'!$E$4:$E$69,$B$3,'Food Safety Program'!$B$4:$B$69,"<>") -> 0 | D10: =COUNTIFS('Food Safety Program'!$D$4:$D$69,">0",'Food Safety Program'!$D$4:$D$69,"<="&$B$3,'Food Safety Program'!$E$4:$E$69,">="&$B$3,'Food Safety Program'!$B$4:$B$69,"<>") -> 0 | E10: =COUNTIFS('Food Safety Program'!$E$4:$E$69,"<"&$B$3,'Food Safety Program'!$E$4:$E$69,">0",'Food Safety Program'!$O$4:$O$69,"<1") -> 17 | F10: =COUNTIFS('Food Safety Program'!$O$4:$O$69,1) -> 49 | G10: =COUNTIFS('Food Safety Program'!$O$4:$O$69,">0",'Food Safety Program'!$O$4:$O$69,"<1") -> 17 | H10: =COUNTIFS('Food Safety Program'!$O$4:$O$69,0) -> 0 | I10: =COUNT('Food Safety Program'!$O$4:$O$69) -> 66 | J10: =IFERROR(AVERAGE('Food Safety Program'!$O$4:$O$69),0) -> 0.85795455 | K10: =IF(J10=1,"Complete",IF(J10>=0.5,"On Track",IF(J10>0,"At Risk","Not Started"))) -> On Track | M10: =M9+1 -> #REF! | N10: =TEXT($M10,"ddd") -> #REF! | O10: =COUNTIFS('AI Agents'!$D$5:$D$36,$M10,'AI Agents'!$B$5:$B$36,"<>")+COUNTIFS('SG Website Plan'!$D$4:$D$41,$M10,'SG Website Plan'!$B$4:$B$41,"<>")+COUNTIFS('Food Safety Program'!$D$4:$D$69,$M10,'Food Safety Program'!$B$4:$B$69,"<>")+COUNTIFS('C-SAT Survey'!$D$4:$D$75,$M10,'C-SAT Survey'!$B$4:$B$75,"<>")+COUNTIFS('GPM&I'!$E$4:$E$115,$M10,'GPM&I'!$C$4:$C$115,"<>")+COUNTIFS('Trio Academy(LMS)'!$D$4:$D$164,$M10,'Trio Academy(LMS)'!$B$4:$B$164,"<>") -> 0 | P10: =COUNTIFS('AI Agents'!$E$5:$E$36,$M10,'AI Agents'!$B$5:$B$36,"<>")+COUNTIFS('SG Website Plan'!$E$4:$E$41,$M10,'SG Website Plan'!$B$4:$B$41,"<>")+COUNTIFS('Food Safety Program'!$E$4:$E$69,$M10,'Food Safety Program'!$B$4:$B$69,"<>")+COUNTIFS('C-SAT Survey'!$E$4:$E$75,$M10,'C-SAT Survey'!$B$4:$B$75,"<>")+COUNTIFS('GPM&I'!$F$4:$F$115,$M10,'GPM&I'!$C$4:$C$115,"<>")+COUNTIFS('Trio Academy(LMS)'!$E$4:$E$164,$M10,'Trio Academy(LMS)'!$B$4:$B$164,"<>") -> 0 | Q10: =COUNTIFS('AI Agents'!$D$5:$D$36,">0",'AI Agents'!$D$5:$D$36,"<="&$M10,'AI Agents'!$E$5:$E$36,">="&$M10,'AI Agents'!$B$5:$B$36,"<>")+COUNTIFS('SG Website Plan'!$D$4:$D$41,">0",'SG Website Plan'!$D$4:$D$41,"<="&$M10,'SG Website Plan'!$E$4:$E$41,">="&$M10,'SG Website Plan'!$B$4:$B$41,"<>")+COUNTIFS('Food Safety Program'!$D$4:$D$69,">0",'Food Safety Program'!$D$4:$D$69,"<="&$M10,'Food Safety Program'!$E$4:$E$69,">="&$M10,'Food Safety Program'!$B$4:$B$69,"<>")+COUNTIFS('C-SAT Survey'!$D$4:$D$75,">0",'C-SAT Survey'!$D$4:$D$75,"<="&$M10,'C-SAT Survey'!$E$4:$E$75,">="&$M10,'C-SAT Survey'!$B$4:$B$75,"<>")+COUNTIFS('GPM&I'!$E$4:$E$115,">0",'GPM&I'!$E$4:$E$115,"<="&$M10,'GPM&I'!$F$4:$F$115,">="&$M10,'GPM&I'!$C$4:$C$115,"<>")+COUNTIFS('Trio Academy(LMS)'!$D$4:$D$164,">0",'Trio Academy(LMS)'!$D$4:$D$164,"<="&$M10,'Trio Academy(LMS)'!$E$4:$E$164,">="&$M10,'Trio Academy(LMS)'!$B$4:$B$164,"<>") -> 0 | R10: =COUNTIFS('AI Agents'!$E$5:$E$36,"<"&$M10,'AI Agents'!$E$5:$E$36,">0",'AI Agents'!$N$5:$N$36,"<1")+COUNTIFS('SG Website Plan'!$E$4:$E$41,"<"&$M10,'SG Website Plan'!$E$4:$E$41,">0",'SG Website Plan'!$L$4:$L$41,"<1")+COUNTIFS('Food Safety Program'!$E$4:$E$69,"<"&$M10,'Food Safety Program'!$E$4:$E$69,">0",'Food Safety Program'!$O$4:$O$69,"<1")+COUNTIFS('C-SAT Survey'!$E$4:$E$75,"<"&$M10,'C-SAT Survey'!$E$4:$E$75,">0",'C-SAT Survey'!$M$4:$M$75,"<1")+COUNTIFS('GPM&I'!$F$4:$F$115,"<"&$M10,'GPM&I'!$F$4:$F$115,">0",'GPM&I'!$M$4:$M$115,"<1")+COUNTIFS('Trio Academy(LMS)'!$E$4:$E$164,"<"&$M10,'Trio Academy(LMS)'!$E$4:$E$164,">0",'Trio Academy(LMS)'!$L$4:$L$164,"<1") -> 0
A11: C-SAT Survey | B11: =COUNTIFS('C-SAT Survey'!$D$4:$D$75,$B$3,'C-SAT Survey'!$B$4:$B$75,"<>") -> 0 | C11: =COUNTIFS('C-SAT Survey'!$E$4:$E$75,$B$3,'C-SAT Survey'!$B$4:$B$75,"<>") -> 7 | D11: =COUNTIFS('C-SAT Survey'!$D$4:$D$75,">0",'C-SAT Survey'!$D$4:$D$75,"<="&$B$3,'C-SAT Survey'!$E$4:$E$75,">="&$B$3,'C-SAT Survey'!$B$4:$B$75,"<>") -> 42 | E11: =COUNTIFS('C-SAT Survey'!$E$4:$E$75,"<"&$B$3,'C-SAT Survey'!$E$4:$E$75,">0",'C-SAT Survey'!$M$4:$M$75,"<1") -> 0 | F11: =COUNTIFS('C-SAT Survey'!$M$4:$M$75,1) -> 57 | G11: =COUNTIFS('C-SAT Survey'!$M$4:$M$75,">0",'C-SAT Survey'!$M$4:$M$75,"<1") -> 0 | H11: =COUNTIFS('C-SAT Survey'!$M$4:$M$75,0) -> 8 | I11: =COUNT('C-SAT Survey'!$M$4:$M$75) -> 65 | J11: =IFERROR(AVERAGE('C-SAT Survey'!$M$4:$M$75),0) -> 0.87692308 | K11: =IF(J11=1,"Complete",IF(J11>=0.5,"On Track",IF(J11>0,"At Risk","Not Started"))) -> On Track | M11: =M10+1 -> #REF! | N11: =TEXT($M11,"ddd") -> #REF! | O11: =COUNTIFS('AI Agents'!$D$5:$D$36,$M11,'AI Agents'!$B$5:$B$36,"<>")+COUNTIFS('SG Website Plan'!$D$4:$D$41,$M11,'SG Website Plan'!$B$4:$B$41,"<>")+COUNTIFS('Food Safety Program'!$D$4:$D$69,$M11,'Food Safety Program'!$B$4:$B$69,"<>")+COUNTIFS('C-SAT Survey'!$D$4:$D$75,$M11,'C-SAT Survey'!$B$4:$B$75,"<>")+COUNTIFS('GPM&I'!$E$4:$E$115,$M11,'GPM&I'!$C$4:$C$115,"<>")+COUNTIFS('Trio Academy(LMS)'!$D$4:$D$164,$M11,'Trio Academy(LMS)'!$B$4:$B$164,"<>") -> 0 | P11: =COUNTIFS('AI Agents'!$E$5:$E$36,$M11,'AI Agents'!$B$5:$B$36,"<>")+COUNTIFS('SG Website Plan'!$E$4:$E$41,$M11,'SG Website Plan'!$B$4:$B$41,"<>")+COUNTIFS('Food Safety Program'!$E$4:$E$69,$M11,'Food Safety Program'!$B$4:$B$69,"<>")+COUNTIFS('C-SAT Survey'!$E$4:$E$75,$M11,'C-SAT Survey'!$B$4:$B$75,"<>")+COUNTIFS('GPM&I'!$F$4:$F$115,$M11,'GPM&I'!$C$4:$C$115,"<>")+COUNTIFS('Trio Academy(LMS)'!$E$4:$E$164,$M11,'Trio Academy(LMS)'!$B$4:$B$164,"<>") -> 0 | Q11: =COUNTIFS('AI Agents'!$D$5:$D$36,">0",'AI Agents'!$D$5:$D$36,"<="&$M11,'AI Agents'!$E$5:$E$36,">="&$M11,'AI Agents'!$B$5:$B$36,"<>")+COUNTIFS('SG Website Plan'!$D$4:$D$41,">0",'SG Website Plan'!$D$4:$D$41,"<="&$M11,'SG Website Plan'!$E$4:$E$41,">="&$M11,'SG Website Plan'!$B$4:$B$41,"<>")+COUNTIFS('Food Safety Program'!$D$4:$D$69,">0",'Food Safety Program'!$D$4:$D$69,"<="&$M11,'Food Safety Program'!$E$4:$E$69,">="&$M11,'Food Safety Program'!$B$4:$B$69,"<>")+COUNTIFS('C-SAT Survey'!$D$4:$D$75,">0",'C-SAT Survey'!$D$4:$D$75,"<="&$M11,'C-SAT Survey'!$E$4:$E$75,">="&$M11,'C-SAT Survey'!$B$4:$B$75,"<>")+COUNTIFS('GPM&I'!$E$4:$E$115,">0",'GPM&I'!$E$4:$E$115,"<="&$M11,'GPM&I'!$F$4:$F$115,">="&$M11,'GPM&I'!$C$4:$C$115,"<>")+COUNTIFS('Trio Academy(LMS)'!$D$4:$D$164,">0",'Trio Academy(LMS)'!$D$4:$D$164,"<="&$M11,'Trio Academy(LMS)'!$E$4:$E$164,">="&$M11,'Trio Academy(LMS)'!$B$4:$B$164,"<>") -> 0 | R11: =COUNTIFS('AI Agents'!$E$5:$E$36,"<"&$M11,'AI Agents'!$E$5:$E$36,">0",'AI Agents'!$N$5:$N$36,"<1")+COUNTIFS('SG Website Plan'!$E$4:$E$41,"<"&$M11,'SG Website Plan'!$E$4:$E$41,">0",'SG Website Plan'!$L$4:$L$41,"<1")+COUNTIFS('Food Safety Program'!$E$4:$E$69,"<"&$M11,'Food Safety Program'!$E$4:$E$69,">0",'Food Safety Program'!$O$4:$O$69,"<1")+COUNTIFS('C-SAT Survey'!$E$4:$E$75,"<"&$M11,'C-SAT Survey'!$E$4:$E$75,">0",'C-SAT Survey'!$M$4:$M$75,"<1")+COUNTIFS('GPM&I'!$F$4:$F$115,"<"&$M11,'GPM&I'!$F$4:$F$115,">0",'GPM&I'!$M$4:$M$115,"<1")+COUNTIFS('Trio Academy(LMS)'!$E$4:$E$164,"<"&$M11,'Trio Academy(LMS)'!$E$4:$E$164,">0",'Trio Academy(LMS)'!$L$4:$L$164,"<1") -> 0
A12: GPM&I Project Plan | B12: =COUNTIFS('GPM&I'!$E$4:$E$115,$B$3,'GPM&I'!$C$4:$C$115,"<>") -> 3 | C12: =COUNTIFS('GPM&I'!$F$4:$F$115,$B$3,'GPM&I'!$C$4:$C$115,"<>") -> 2 | D12: =COUNTIFS('GPM&I'!$E$4:$E$115,">0",'GPM&I'!$E$4:$E$115,"<="&$B$3,'GPM&I'!$F$4:$F$115,">="&$B$3,'GPM&I'!$C$4:$C$115,"<>") -> 3 | E12: =COUNTIFS('GPM&I'!$F$4:$F$115,"<"&$B$3,'GPM&I'!$F$4:$F$115,">0",'GPM&I'!$M$4:$M$115,"<1") -> 7 | F12: =COUNTIFS('GPM&I'!$M$4:$M$115,1) -> 0 | G12: =COUNTIFS('GPM&I'!$M$4:$M$115,">0",'GPM&I'!$M$4:$M$115,"<1") -> 72 | H12: =COUNTIFS('GPM&I'!$M$4:$M$115,0) -> 40 | I12: =COUNT('GPM&I'!$M$4:$M$115) -> 112 | J12: =IFERROR(AVERAGE('GPM&I'!$M$4:$M$115),0) -> 0.42857143 | K12: =IF(J12=1,"Complete",IF(J12>=0.5,"On Track",IF(J12>0,"At Risk","Not Started"))) -> At Risk | M12: =M11+1 -> #REF! | N12: =TEXT($M12,"ddd") -> #REF! | O12: =COUNTIFS('AI Agents'!$D$5:$D$36,$M12,'AI Agents'!$B$5:$B$36,"<>")+COUNTIFS('SG Website Plan'!$D$4:$D$41,$M12,'SG Website Plan'!$B$4:$B$41,"<>")+COUNTIFS('Food Safety Program'!$D$4:$D$69,$M12,'Food Safety Program'!$B$4:$B$69,"<>")+COUNTIFS('C-SAT Survey'!$D$4:$D$75,$M12,'C-SAT Survey'!$B$4:$B$75,"<>")+COUNTIFS('GPM&I'!$E$4:$E$115,$M12,'GPM&I'!$C$4:$C$115,"<>")+COUNTIFS('Trio Academy(LMS)'!$D$4:$D$164,$M12,'Trio Academy(LMS)'!$B$4:$B$164,"<>") -> 0 | P12: =COUNTIFS('AI Agents'!$E$5:$E$36,$M12,'AI Agents'!$B$5:$B$36,"<>")+COUNTIFS('SG Website Plan'!$E$4:$E$41,$M12,'SG Website Plan'!$B$4:$B$41,"<>")+COUNTIFS('Food Safety Program'!$E$4:$E$69,$M12,'Food Safety Program'!$B$4:$B$69,"<>")+COUNTIFS('C-SAT Survey'!$E$4:$E$75,$M12,'C-SAT Survey'!$B$4:$B$75,"<>")+COUNTIFS('GPM&I'!$F$4:$F$115,$M12,'GPM&I'!$C$4:$C$115,"<>")+COUNTIFS('Trio Academy(LMS)'!$E$4:$E$164,$M12,'Trio Academy(LMS)'!$B$4:$B$164,"<>") -> 0 | Q12: =COUNTIFS('AI Agents'!$D$5:$D$36,">0",'AI Agents'!$D$5:$D$36,"<="&$M12,'AI Agents'!$E$5:$E$36,">="&$M12,'AI Agents'!$B$5:$B$36,"<>")+COUNTIFS('SG Website Plan'!$D$4:$D$41,">0",'SG Website Plan'!$D$4:$D$41,"<="&$M12,'SG Website Plan'!$E$4:$E$41,">="&$M12,'SG Website Plan'!$B$4:$B$41,"<>")+COUNTIFS('Food Safety Program'!$D$4:$D$69,">0",'Food Safety Program'!$D$4:$D$69,"<="&$M12,'Food Safety Program'!$E$4:$E$69,">="&$M12,'Food Safety Program'!$B$4:$B$69,"<>")+COUNTIFS('C-SAT Survey'!$D$4:$D$75,">0",'C-SAT Survey'!$D$4:$D$75,"<="&$M12,'C-SAT Survey'!$E$4:$E$75,">="&$M12,'C-SAT Survey'!$B$4:$B$75,"<>")+COUNTIFS('GPM&I'!$E$4:$E$115,">0",'GPM&I'!$E$4:$E$115,"<="&$M12,'GPM&I'!$F$4:$F$115,">="&$M12,'GPM&I'!$C$4:$C$115,"<>")+COUNTIFS('Trio Academy(LMS)'!$D$4:$D$164,">0",'Trio Academy(LMS)'!$D$4:$D$164,"<="&$M12,'Trio Academy(LMS)'!$E$4:$E$164,">="&$M12,'Trio Academy(LMS)'!$B$4:$B$164,"<>") -> 0 | R12: =COUNTIFS('AI Agents'!$E$5:$E$36,"<"&$M12,'AI Agents'!$E$5:$E$36,">0",'AI Agents'!$N$5:$N$36,"<1")+COUNTIFS('SG Website Plan'!$E$4:$E$41,"<"&$M12,'SG Website Plan'!$E$4:$E$41,">0",'SG Website Plan'!$L$4:$L$41,"<1")+COUNTIFS('Food Safety Program'!$E$4:$E$69,"<"&$M12,'Food Safety Program'!$E$4:$E$69,">0",'Food Safety Program'!$O$4:$O$69,"<1")+COUNTIFS('C-SAT Survey'!$E$4:$E$75,"<"&$M12,'C-SAT Survey'!$E$4:$E$75,">0",'C-SAT Survey'!$M$4:$M$75,"<1")+COUNTIFS('GPM&I'!$F$4:$F$115,"<"&$M12,'GPM&I'!$F$4:$F$115,">0",'GPM&I'!$M$4:$M$115,"<1")+COUNTIFS('Trio Academy(LMS)'!$E$4:$E$164,"<"&$M12,'Trio Academy(LMS)'!$E$4:$E$164,">0",'Trio Academy(LMS)'!$L$4:$L$164,"<1") -> 0
A13: Trio Academy(LMS) | B13: =COUNTIFS('Trio Academy(LMS)'!$D$4:$D$164,$B$3,'Trio Academy(LMS)'!$B$4:$B$164,"<>") -> 0 | C13: =COUNTIFS('Trio Academy(LMS)'!$E$4:$E$164,$B$3,'Trio Academy(LMS)'!$B$4:$B$164,"<>") -> 0 | D13: =COUNTIFS('Trio Academy(LMS)'!$D$4:$D$164,">0",'Trio Academy(LMS)'!$D$4:$D$164,"<="&$B$3,'Trio Academy(LMS)'!$E$4:$E$164,">="&$B$3,'Trio Academy(LMS)'!$B$4:$B$164,"<>") -> 0 | E13: =COUNTIFS('Trio Academy(LMS)'!$E$4:$E$164,"<"&$B$3,'Trio Academy(LMS)'!$E$4:$E$164,">0",'Trio Academy(LMS)'!$L$4:$L$164,"<1") -> 2 | F13: =COUNTIFS('Trio Academy(LMS)'!$L$4:$L$164,1) -> 159 | G13: =COUNTIFS('Trio Academy(LMS)'!$L$4:$L$164,">0",'Trio Academy(LMS)'!$L$4:$L$164,"<1") -> 2 | H13: =COUNTIFS('Trio Academy(LMS)'!$L$4:$L$164,0) -> 0 | I13: =COUNT('Trio Academy(LMS)'!$L$4:$L$164) -> 161 | J13: =IFERROR(AVERAGE('Trio Academy(LMS)'!$L$4:$L$164),0) -> 0.99378882 | K13: =IF(J13=1,"Complete",IF(J13>=0.5,"On Track",IF(J13>0,"At Risk","Not Started"))) -> On Track | M13: =M12+1 -> #REF! | N13: =TEXT($M13,"ddd") -> #REF! | O13: =COUNTIFS('AI Agents'!$D$5:$D$36,$M13,'AI Agents'!$B$5:$B$36,"<>")+COUNTIFS('SG Website Plan'!$D$4:$D$41,$M13,'SG Website Plan'!$B$4:$B$41,"<>")+COUNTIFS('Food Safety Program'!$D$4:$D$69,$M13,'Food Safety Program'!$B$4:$B$69,"<>")+COUNTIFS('C-SAT Survey'!$D$4:$D$75,$M13,'C-SAT Survey'!$B$4:$B$75,"<>")+COUNTIFS('GPM&I'!$E$4:$E$115,$M13,'GPM&I'!$C$4:$C$115,"<>")+COUNTIFS('Trio Academy(LMS)'!$D$4:$D$164,$M13,'Trio Academy(LMS)'!$B$4:$B$164,"<>") -> 0 | P13: =COUNTIFS('AI Agents'!$E$5:$E$36,$M13,'AI Agents'!$B$5:$B$36,"<>")+COUNTIFS('SG Website Plan'!$E$4:$E$41,$M13,'SG Website Plan'!$B$4:$B$41,"<>")+COUNTIFS('Food Safety Program'!$E$4:$E$69,$M13,'Food Safety Program'!$B$4:$B$69,"<>")+COUNTIFS('C-SAT Survey'!$E$4:$E$75,$M13,'C-SAT Survey'!$B$4:$B$75,"<>")+COUNTIFS('GPM&I'!$F$4:$F$115,$M13,'GPM&I'!$C$4:$C$115,"<>")+COUNTIFS('Trio Academy(LMS)'!$E$4:$E$164,$M13,'Trio Academy(LMS)'!$B$4:$B$164,"<>") -> 0 | Q13: =COUNTIFS('AI Agents'!$D$5:$D$36,">0",'AI Agents'!$D$5:$D$36,"<="&$M13,'AI Agents'!$E$5:$E$36,">="&$M13,'AI Agents'!$B$5:$B$36,"<>")+COUNTIFS('SG Website Plan'!$D$4:$D$41,">0",'SG Website Plan'!$D$4:$D$41,"<="&$M13,'SG Website Plan'!$E$4:$E$41,">="&$M13,'SG Website Plan'!$B$4:$B$41,"<>")+COUNTIFS('Food Safety Program'!$D$4:$D$69,">0",'Food Safety Program'!$D$4:$D$69,"<="&$M13,'Food Safety Program'!$E$4:$E$69,">="&$M13,'Food Safety Program'!$B$4:$B$69,"<>")+COUNTIFS('C-SAT Survey'!$D$4:$D$75,">0",'C-SAT Survey'!$D$4:$D$75,"<="&$M13,'C-SAT Survey'!$E$4:$E$75,">="&$M13,'C-SAT Survey'!$B$4:$B$75,"<>")+COUNTIFS('GPM&I'!$E$4:$E$115,">0",'GPM&I'!$E$4:$E$115,"<="&$M13,'GPM&I'!$F$4:$F$115,">="&$M13,'GPM&I'!$C$4:$C$115,"<>")+COUNTIFS('Trio Academy(LMS)'!$D$4:$D$164,">0",'Trio Academy(LMS)'!$D$4:$D$164,"<="&$M13,'Trio Academy(LMS)'!$E$4:$E$164,">="&$M13,'Trio Academy(LMS)'!$B$4:$B$164,"<>") -> 0 | R13: =COUNTIFS('AI Agents'!$E$5:$E$36,"<"&$M13,'AI Agents'!$E$5:$E$36,">0",'AI Agents'!$N$5:$N$36,"<1")+COUNTIFS('SG Website Plan'!$E$4:$E$41,"<"&$M13,'SG Website Plan'!$E$4:$E$41,">0",'SG Website Plan'!$L$4:$L$41,"<1")+COUNTIFS('Food Safety Program'!$E$4:$E$69,"<"&$M13,'Food Safety Program'!$E$4:$E$69,">0",'Food Safety Program'!$O$4:$O$69,"<1")+COUNTIFS('C-SAT Survey'!$E$4:$E$75,"<"&$M13,'C-SAT Survey'!$E$4:$E$75,">0",'C-SAT Survey'!$M$4:$M$75,"<1")+COUNTIFS('GPM&I'!$F$4:$F$115,"<"&$M13,'GPM&I'!$F$4:$F$115,">0",'GPM&I'!$M$4:$M$115,"<1")+COUNTIFS('Trio Academy(LMS)'!$E$4:$E$164,"<"&$M13,'Trio Academy(LMS)'!$E$4:$E$164,">0",'Trio Academy(LMS)'!$L$4:$L$164,"<1") -> 0
A14: TOTAL / OVERALL | B14: =SUM(B8:B13) -> 3 | C14: =SUM(C8:C13) -> 9 | D14: =SUM(D8:D13) -> 45 | E14: =SUM(E8:E13) -> 36 | F14: =SUM(F8:F13) -> 316 | G14: =SUM(G8:G13) -> 99 | H14: =SUM(H8:H13) -> 50 | I14: =SUM(I8:I13) -> 465 | J14: =IFERROR(F14/I14,0) -> 0.67956989 | K14: =IF(J14=1,"Complete",IF(J14>=0.5,"On Track","At Risk")) -> On Track | M14: =M13+1 -> #REF! | N14: =TEXT($M14,"ddd") -> #REF! | O14: =COUNTIFS('AI Agents'!$D$5:$D$36,$M14,'AI Agents'!$B$5:$B$36,"<>")+COUNTIFS('SG Website Plan'!$D$4:$D$41,$M14,'SG Website Plan'!$B$4:$B$41,"<>")+COUNTIFS('Food Safety Program'!$D$4:$D$69,$M14,'Food Safety Program'!$B$4:$B$69,"<>")+COUNTIFS('C-SAT Survey'!$D$4:$D$75,$M14,'C-SAT Survey'!$B$4:$B$75,"<>")+COUNTIFS('GPM&I'!$E$4:$E$115,$M14,'GPM&I'!$C$4:$C$115,"<>")+COUNTIFS('Trio Academy(LMS)'!$D$4:$D$164,$M14,'Trio Academy(LMS)'!$B$4:$B$164,"<>") -> 0 | P14: =COUNTIFS('AI Agents'!$E$5:$E$36,$M14,'AI Agents'!$B$5:$B$36,"<>")+COUNTIFS('SG Website Plan'!$E$4:$E$41,$M14,'SG Website Plan'!$B$4:$B$41,"<>")+COUNTIFS('Food Safety Program'!$E$4:$E$69,$M14,'Food Safety Program'!$B$4:$B$69,"<>")+COUNTIFS('C-SAT Survey'!$E$4:$E$75,$M14,'C-SAT Survey'!$B$4:$B$75,"<>")+COUNTIFS('GPM&I'!$F$4:$F$115,$M14,'GPM&I'!$C$4:$C$115,"<>")+COUNTIFS('Trio Academy(LMS)'!$E$4:$E$164,$M14,'Trio Academy(LMS)'!$B$4:$B$164,"<>") -> 0 | Q14: =COUNTIFS('AI Agents'!$D$5:$D$36,">0",'AI Agents'!$D$5:$D$36,"<="&$M14,'AI Agents'!$E$5:$E$36,">="&$M14,'AI Agents'!$B$5:$B$36,"<>")+COUNTIFS('SG Website Plan'!$D$4:$D$41,">0",'SG Website Plan'!$D$4:$D$41,"<="&$M14,'SG Website Plan'!$E$4:$E$41,">="&$M14,'SG Website Plan'!$B$4:$B$41,"<>")+COUNTIFS('Food Safety Program'!$D$4:$D$69,">0",'Food Safety Program'!$D$4:$D$69,"<="&$M14,'Food Safety Program'!$E$4:$E$69,">="&$M14,'Food Safety Program'!$B$4:$B$69,"<>")+COUNTIFS('C-SAT Survey'!$D$4:$D$75,">0",'C-SAT Survey'!$D$4:$D$75,"<="&$M14,'C-SAT Survey'!$E$4:$E$75,">="&$M14,'C-SAT Survey'!$B$4:$B$75,"<>")+COUNTIFS('GPM&I'!$E$4:$E$115,">0",'GPM&I'!$E$4:$E$115,"<="&$M14,'GPM&I'!$F$4:$F$115,">="&$M14,'GPM&I'!$C$4:$C$115,"<>")+COUNTIFS('Trio Academy(LMS)'!$D$4:$D$164,">0",'Trio Academy(LMS)'!$D$4:$D$164,"<="&$M14,'Trio Academy(LMS)'!$E$4:$E$164,">="&$M14,'Trio Academy(LMS)'!$B$4:$B$164,"<>") -> 0 | R14: =COUNTIFS('AI Agents'!$E$5:$E$36,"<"&$M14,'AI Agents'!$E$5:$E$36,">0",'AI Agents'!$N$5:$N$36,"<1")+COUNTIFS('SG Website Plan'!$E$4:$E$41,"<"&$M14,'SG Website Plan'!$E$4:$E$41,">0",'SG Website Plan'!$L$4:$L$41,"<1")+COUNTIFS('Food Safety Program'!$E$4:$E$69,"<"&$M14,'Food Safety Program'!$E$4:$E$69,">0",'Food Safety Program'!$O$4:$O$69,"<1")+COUNTIFS('C-SAT Survey'!$E$4:$E$75,"<"&$M14,'C-SAT Survey'!$E$4:$E$75,">0",'C-SAT Survey'!$M$4:$M$75,"<1")+COUNTIFS('GPM&I'!$F$4:$F$115,"<"&$M14,'GPM&I'!$F$4:$F$115,">0",'GPM&I'!$M$4:$M$115,"<1")+COUNTIFS('Trio Academy(LMS)'!$E$4:$E$164,"<"&$M14,'Trio Academy(LMS)'!$E$4:$E$164,">0",'Trio Academy(LMS)'!$L$4:$L$164,"<1") -> 0
M15: =M14+1 -> #REF! | N15: =TEXT($M15,"ddd") -> #REF! | O15: =COUNTIFS('AI Agents'!$D$5:$D$36,$M15,'AI Agents'!$B$5:$B$36,"<>")+COUNTIFS('SG Website Plan'!$D$4:$D$41,$M15,'SG Website Plan'!$B$4:$B$41,"<>")+COUNTIFS('Food Safety Program'!$D$4:$D$69,$M15,'Food Safety Program'!$B$4:$B$69,"<>")+COUNTIFS('C-SAT Survey'!$D$4:$D$75,$M15,'C-SAT Survey'!$B$4:$B$75,"<>")+COUNTIFS('GPM&I'!$E$4:$E$115,$M15,'GPM&I'!$C$4:$C$115,"<>")+COUNTIFS('Trio Academy(LMS)'!$D$4:$D$164,$M15,'Trio Academy(LMS)'!$B$4:$B$164,"<>") -> 0 | P15: =COUNTIFS('AI Agents'!$E$5:$E$36,$M15,'AI Agents'!$B$5:$B$36,"<>")+COUNTIFS('SG Website Plan'!$E$4:$E$41,$M15,'SG Website Plan'!$B$4:$B$41,"<>")+COUNTIFS('Food Safety Program'!$E$4:$E$69,$M15,'Food Safety Program'!$B$4:$B$69,"<>")+COUNTIFS('C-SAT Survey'!$E$4:$E$75,$M15,'C-SAT Survey'!$B$4:$B$75,"<>")+COUNTIFS('GPM&I'!$F$4:$F$115,$M15,'GPM&I'!$C$4:$C$115,"<>")+COUNTIFS('Trio Academy(LMS)'!$E$4:$E$164,$M15,'Trio Academy(LMS)'!$B$4:$B$164,"<>") -> 0 | Q15: =COUNTIFS('AI Agents'!$D$5:$D$36,">0",'AI Agents'!$D$5:$D$36,"<="&$M15,'AI Agents'!$E$5:$E$36,">="&$M15,'AI Agents'!$B$5:$B$36,"<>")+COUNTIFS('SG Website Plan'!$D$4:$D$41,">0",'SG Website Plan'!$D$4:$D$41,"<="&$M15,'SG Website Plan'!$E$4:$E$41,">="&$M15,'SG Website Plan'!$B$4:$B$41,"<>")+COUNTIFS('Food Safety Program'!$D$4:$D$69,">0",'Food Safety Program'!$D$4:$D$69,"<="&$M15,'Food Safety Program'!$E$4:$E$69,">="&$M15,'Food Safety Program'!$B$4:$B$69,"<>")+COUNTIFS('C-SAT Survey'!$D$4:$D$75,">0",'C-SAT Survey'!$D$4:$D$75,"<="&$M15,'C-SAT Survey'!$E$4:$E$75,">="&$M15,'C-SAT Survey'!$B$4:$B$75,"<>")+COUNTIFS('GPM&I'!$E$4:$E$115,">0",'GPM&I'!$E$4:$E$115,"<="&$M15,'GPM&I'!$F$4:$F$115,">="&$M15,'GPM&I'!$C$4:$C$115,"<>")+COUNTIFS('Trio Academy(LMS)'!$D$4:$D$164,">0",'Trio Academy(LMS)'!$D$4:$D$164,"<="&$M15,'Trio Academy(LMS)'!$E$4:$E$164,">="&$M15,'Trio Academy(LMS)'!$B$4:$B$164,"<>") -> 0 | R15: =COUNTIFS('AI Agents'!$E$5:$E$36,"<"&$M15,'AI Agents'!$E$5:$E$36,">0",'AI Agents'!$N$5:$N$36,"<1")+COUNTIFS('SG Website Plan'!$E$4:$E$41,"<"&$M15,'SG Website Plan'!$E$4:$E$41,">0",'SG Website Plan'!$L$4:$L$41,"<1")+COUNTIFS('Food Safety Program'!$E$4:$E$69,"<"&$M15,'Food Safety Program'!$E$4:$E$69,">0",'Food Safety Program'!$O$4:$O$69,"<1")+COUNTIFS('C-SAT Survey'!$E$4:$E$75,"<"&$M15,'C-SAT Survey'!$E$4:$E$75,">0",'C-SAT Survey'!$M$4:$M$75,"<1")+COUNTIFS('GPM&I'!$F$4:$F$115,"<"&$M15,'GPM&I'!$F$4:$F$115,">0",'GPM&I'!$M$4:$M$115,"<1")+COUNTIFS('Trio Academy(LMS)'!$E$4:$E$164,"<"&$M15,'Trio Academy(LMS)'!$E$4:$E$164,">0",'Trio Academy(LMS)'!$L$4:$L$164,"<1") -> 0
A16: TASK DETAIL — ACTIVE ON REPORT DATE + OVERDUE OPEN ITEMS | O16: =COUNTIFS('AI Agents'!$D$5:$D$36,$M16,'AI Agents'!$B$5:$B$36,"<>")+COUNTIFS('SG Website Plan'!$D$4:$D$41,$M16,'SG Website Plan'!$B$4:$B$41,"<>")+COUNTIFS('Food Safety Program'!$D$4:$D$69,$M16,'Food Safety Program'!$B$4:$B$69,"<>")+COUNTIFS('C-SAT Survey'!$D$4:$D$75,$M16,'C-SAT Survey'!$B$4:$B$75,"<>")+COUNTIFS('GPM&I'!$E$4:$E$115,$M16,'GPM&I'!$C$4:$C$115,"<>")+COUNTIFS('Trio Academy(LMS)'!$D$4:$D$164,$M16,'Trio Academy(LMS)'!$B$4:$B$164,"<>") -> 0 | P16: =COUNTIFS('AI Agents'!$E$5:$E$36,$M16,'AI Agents'!$B$5:$B$36,"<>")+COUNTIFS('SG Website Plan'!$E$4:$E$41,$M16,'SG Website Plan'!$B$4:$B$41,"<>")+COUNTIFS('Food Safety Program'!$E$4:$E$69,$M16,'Food Safety Program'!$B$4:$B$69,"<>")+COUNTIFS('C-SAT Survey'!$E$4:$E$75,$M16,'C-SAT Survey'!$B$4:$B$75,"<>")+COUNTIFS('GPM&I'!$F$4:$F$115,$M16,'GPM&I'!$C$4:$C$115,"<>")+COUNTIFS('Trio Academy(LMS)'!$E$4:$E$164,$M16,'Trio Academy(LMS)'!$B$4:$B$164,"<>") -> 0 | Q16: =COUNTIFS('AI Agents'!$D$5:$D$36,">0",'AI Agents'!$D$5:$D$36,"<="&$M16,'AI Agents'!$E$5:$E$36,">="&$M16,'AI Agents'!$B$5:$B$36,"<>")+COUNTIFS('SG Website Plan'!$D$4:$D$41,">0",'SG Website Plan'!$D$4:$D$41,"<="&$M16,'SG Website Plan'!$E$4:$E$41,">="&$M16,'SG Website Plan'!$B$4:$B$41,"<>")+COUNTIFS('Food Safety Program'!$D$4:$D$69,">0",'Food Safety Program'!$D$4:$D$69,"<="&$M16,'Food Safety Program'!$E$4:$E$69,">="&$M16,'Food Safety Program'!$B$4:$B$69,"<>")+COUNTIFS('C-SAT Survey'!$D$4:$D$75,">0",'C-SAT Survey'!$D$4:$D$75,"<="&$M16,'C-SAT Survey'!$E$4:$E$75,">="&$M16,'C-SAT Survey'!$B$4:$B$75,"<>")+COUNTIFS('GPM&I'!$E$4:$E$115,">0",'GPM&I'!$E$4:$E$115,"<="&$M16,'GPM&I'!$F$4:$F$115,">="&$M16,'GPM&I'!$C$4:$C$115,"<>")+COUNTIFS('Trio Academy(LMS)'!$D$4:$D$164,">0",'Trio Academy(LMS)'!$D$4:$D$164,"<="&$M16,'Trio Academy(LMS)'!$E$4:$E$164,">="&$M16,'Trio Academy(LMS)'!$B$4:$B$164,"<>") -> 0 | R16: =COUNTIFS('AI Agents'!$E$5:$E$36,"<"&$M16,'AI Agents'!$E$5:$E$36,">0",'AI Agents'!$N$5:$N$36,"<1")+COUNTIFS('SG Website Plan'!$E$4:$E$41,"<"&$M16,'SG Website Plan'!$E$4:$E$41,">0",'SG Website Plan'!$L$4:$L$41,"<1")+COUNTIFS('Food Safety Program'!$E$4:$E$69,"<"&$M16,'Food Safety Program'!$E$4:$E$69,">0",'Food Safety Program'!$O$4:$O$69,"<1")+COUNTIFS('C-SAT Survey'!$E$4:$E$75,"<"&$M16,'C-SAT Survey'!$E$4:$E$75,">0",'C-SAT Survey'!$M$4:$M$75,"<1")+COUNTIFS('GPM&I'!$F$4:$F$115,"<"&$M16,'GPM&I'!$F$4:$F$115,">0",'GPM&I'!$M$4:$M$115,"<1")+COUNTIFS('Trio Academy(LMS)'!$E$4:$E$164,"<"&$M16,'Trio Academy(LMS)'!$E$4:$E$164,">0",'Trio Academy(LMS)'!$L$4:$L$164,"<1") -> 0
A17: Project | B17: Task | C17: Resp | D17: Start Date | E17: End Date | F17: Done % | G17: Day Flag | H17: Days to Due
A18: {=_xlfn.LET(_xlpm.r,_xlfn.VSTACK(IFERROR(_xlfn._xlws.FILTER(_xlfn.HSTACK(IF('AI Agents'!$B$5:$B$36="","AI Agents (Mail Digest)","AI Agents (Mail Digest)"),'AI Agents'!$B$5:$B$36,'AI Agents'!$C$5:$C$36,'AI Agents'!$D$5:$D$36,'AI Agents'!$E$5:$E$36,IFERROR('AI Agents'!$N$5:$N$36,0)),('AI Agents'!$B$5:$B$36<>"")*('AI Agents'!$D$5:$D$36>0)*('AI Agents'!$E$5:$E$36>0)*((('AI Agents'!$D$5:$D$36<=$B$3)*('AI Agents'!$E$5:$E$36>=$B$3))+(('AI Agents'!$E$5:$E$36<$B$3)*(IFERROR('AI Agents'!$N$5:$N$36,0)<1))>0)),_xlfn.HSTACK("","","","","","")),IFERROR(_xlfn._xlws.FILTER(_xlfn.HSTACK(IF('SG Website Plan'!$B$4:$B$41="","SG Website Plan","SG Website Plan"),'SG Website Plan'!$B$4:$B$41,'SG Website Plan'!$C$4:$C$41,'SG Website Plan'!$D$4:$D$41,'SG Website Plan'!$E$4:$E$41,IFERROR('SG Website Plan'!$L$4:$L$41,0)),('SG Website Plan'!$B$4:$B$41<>"")*('SG Website Plan'!$D$4:$D$41>0)*('SG Website Plan'!$E$4:$E$41>0)*((('SG Website Plan'!$D$4:$D$41<=$B$3)*('SG Website Plan'!$E$4:$E$41>=$B$3))+(('SG Website Plan'!$E$4:$E$41<$B$3)*(IFERROR('SG Website Plan'!$L$4:$L$41,0)<1))>0)),_xlfn.HSTACK("","","","","","")),IFERROR(_xlfn._xlws.FILTER(_xlfn.HSTACK(IF('Food Safety Program'!$B$4:$B$69="","Food Safety Program","Food Safety Program"),'Food Safety Program'!$B$4:$B$69,'Food Safety Program'!$C$4:$C$69,'Food Safety Program'!$D$4:$D$69,'Food Safety Program'!$E$4:$E$69,IFERROR('Food Safety Program'!$O$4:$O$69,0)),('Food Safety Program'!$B$4:$B$69<>"")*('Food Safety Program'!$D$4:$D$69>0)*('Food Safety Program'!$E$4:$E$69>0)*((('Food Safety Program'!$D$4:$D$69<=$B$3)*('Food Safety Program'!$E$4:$E$69>=$B$3))+(('Food Safety Program'!$E$4:$E$69<$B$3)*(IFERROR('Food Safety Program'!$O$4:$O$69,0)<1))>0)),_xlfn.HSTACK("","","","","","")),IFERROR(_xlfn._xlws.FILTER(_xlfn.HSTACK(IF('C-SAT Survey'!$B$4:$B$75="","C-SAT Survey","C-SAT Survey"),'C-SAT Survey'!$B$4:$B$75,'C-SAT Survey'!$C$4:$C$75,'C-SAT Survey'!$D$4:$D$75,'C-SAT Survey'!$E$4:$E$75,IFERROR('C-SAT Survey'!$M$4:$M$75,0)),('C-SAT Survey'!$B$4:$B$75<>"")*('C-SAT Survey'!$D$4:$D$75>0)*('C-SAT Survey'!$E$4:$E$75>0)*((('C-SAT Survey'!$D$4:$D$75<=$B$3)*('C-SAT Survey'!$E$4:$E$75>=$B$3))+(('C-SAT Survey'!$E$4:$E$75<$B$3)*(IFERROR('C-SAT Survey'!$M$4:$M$75,0)<1))>0)),_xlfn.HSTACK("","","","","","")),IFERROR(_xlfn._xlws.FILTER(_xlfn.HSTACK(IF('GPM&I'!$B$4:$B$115="","GPM&I Project Plan","GPM&I Project Plan"),'GPM&I'!$B$4:$B$115,'GPM&I'!$D$4:$D$115,'GPM&I'!$D$4:$D$115,'GPM&I'!$E$4:$E$115,IFERROR('GPM&I'!$M$4:$M$115,0)),('GPM&I'!$B$4:$B$115<>"")*('GPM&I'!$D$4:$D$115>0)*('GPM&I'!$E$4:$E$115>0)*((('GPM&I'!$D$4:$D$115<=$B$3)*('GPM&I'!$E$4:$E$115>=$B$3))+(('GPM&I'!$E$4:$E$115<$B$3)*(IFERROR('GPM&I'!$M$4:$M$115,0)<1))>0)),_xlfn.HSTACK("","","","","","")),IFERROR(_xlfn._xlws.FILTER(_xlfn.HSTACK(IF('Trio Academy(LMS)'!$B$4:$B$164="","Trio Academy(LMS)","Trio Academy(LMS)"),'Trio Academy(LMS)'!$B$4:$B$164,'Trio Academy(LMS)'!$C$4:$C$164,'Trio Academy(LMS)'!$D$4:$D$164,'Trio Academy(LMS)'!$E$4:$E$164,IFERROR('Trio Academy(LMS)'!$L$4:$L$164,0)),('Trio Academy(LMS)'!$B$4:$B$164<>"")*('Trio Academy(LMS)'!$D$4:$D$164>0)*('Trio Academy(LMS)'!$E$4:$E$164>0)*((('Trio Academy(LMS)'!$D$4:$D$164<=$B$3)*('Trio Academy(LMS)'!$E$4:$E$164>=$B$3))+(('Trio Academy(LMS)'!$E$4:$E$164<$B$3)*(IFERROR('Trio Academy(LMS)'!$L$4:$L$164,0)<1))>0)),_xlfn.HSTACK("","","","","",""))),_xlfn._xlws.FILTER(_xlpm.r,INDEX(_xlpm.r,,2)<>""))} -> AI Agents (Mail Digest) | B18: T15 User acceptance test of live /digest command | C18: IA | D18: 46249 | E18: 46259 | F18: 0.42857143 | G18: =IF($B18="","",IF($E18<$B$3,"OVERDUE",IF($D18=$B$3,"STARTS TODAY",IF($E18=$B$3,"DUE TODAY","IN PROGRESS")))) -> OVERDUE | H18: =IF($B18="","",$E18-$B$3) -> -16
A19: AI Agents (Mail Digest) | B19: T25 Create SMTP credential in n8n | C19: IA | D19: 46259 | E19: 46270 | F19: 0.42857143 | G19: =IF($B19="","",IF($E19<$B$3,"OVERDUE",IF($D19=$B$3,"STARTS TODAY",IF($E19=$B$3,"DUE TODAY","IN PROGRESS")))) -> OVERDUE | H19: =IF($B19="","",$E19-$B$3) -> -5
A20: AI Agents (Mail Digest) | B20: T26 Create Telegram credential for @hemaminibot | C20: IA | D20: 46259 | E20: 46270 | F20: 0.42857143 | G20: =IF($B20="","",IF($E20<$B$3,"OVERDUE",IF($D20=$B$3,"STARTS TODAY",IF($E20=$B$3,"DUE TODAY","IN PROGRESS")))) -> OVERDUE | H20: =IF($B20="","",$E20-$B$3) -> -5
A21: AI Agents (Mail Digest) | B21: T27 Wire new credentials into workflow nodes | C21: IA | D21: 46259 | E21: 46270 | F21: 0.42857143 | G21: =IF($B21="","",IF($E21<$B$3,"OVERDUE",IF($D21=$B$3,"STARTS TODAY",IF($E21=$B$3,"DUE TODAY","IN PROGRESS")))) -> OVERDUE | H21: =IF($B21="","",$E21-$B$3) -> -5
A22: AI Agents (Mail Digest) | B22: T28 Activate all three n8n workflows | C22: IA | D22: 46259 | E22: 46270 | F22: 0.42857143 | G22: =IF($B22="","",IF($E22<$B$3,"OVERDUE",IF($D22=$B$3,"STARTS TODAY",IF($E22=$B$3,"DUE TODAY","IN PROGRESS")))) -> OVERDUE | H22: =IF($B22="","",$E22-$B$3) -> -5
A23: AI Agents (Mail Digest) | B23: T29 Live-verify Mail Capture field mapping | C23: IA | D23: 46259 | E23: 46270 | F23: 0.42857143 | G23: =IF($B23="","",IF($E23<$B$3,"OVERDUE",IF($D23=$B$3,"STARTS TODAY",IF($E23=$B$3,"DUE TODAY","IN PROGRESS")))) -> OVERDUE | H23: =IF($B23="","",$E23-$B$3) -> -5
A24: AI Agents (Mail Digest) | B24: T30 Add Telegram command routing (/high /search /read) | C24: IA | D24: 46259 | E24: 46270 | F24: 0 | G24: =IF($B24="","",IF($E24<$B$3,"OVERDUE",IF($D24=$B$3,"STARTS TODAY",IF($E24=$B$3,"DUE TODAY","IN PROGRESS")))) -> OVERDUE | H24: =IF($B24="","",$E24-$B$3) -> -5
A25: AI Agents (Mail Digest) | B25: T31 Add Data Table retention/cleanup | C25: IA | D25: 46259 | E25: 46270 | F25: 0 | G25: =IF($B25="","",IF($E25<$B$3,"OVERDUE",IF($D25=$B$3,"STARTS TODAY",IF($E25=$B$3,"DUE TODAY","IN PROGRESS")))) -> OVERDUE | H25: =IF($B25="","",$E25-$B$3) -> -5
A26: SG Website Plan | B26: Get Proc Content Writing | C26: IA - MM | D26: 46244 | E26: 46246 | F26: 0.4 | G26: =IF($B26="","",IF($E26<$B$3,"OVERDUE",IF($D26=$B$3,"STARTS TODAY",IF($E26=$B$3,"DUE TODAY","IN PROGRESS")))) -> OVERDUE | H26: =IF($B26="","",$E26-$B$3) -> -29
A27: SG Website Plan | B27: Get SS&C Content Writing | C27: IA - MM | D27: 46244 | E27: 46246 | F27: 0.8 | G27: =IF($B27="","",IF($E27<$B$3,"OVERDUE",IF($D27=$B$3,"STARTS TODAY",IF($E27=$B$3,"DUE TODAY","IN PROGRESS")))) -> OVERDUE | H27: =IF($B27="","",$E27-$B$3) -> -29
A28: Food Safety Program | B28: LMS Marketing Campain | C28: MAS - IA -MM | D28: 46228 | E28: 46266 | F28: 0.625 | G28: =IF($B28="","",IF($E28<$B$3,"OVERDUE",IF($D28=$B$3,"STARTS TODAY",IF($E28=$B$3,"DUE TODAY","IN PROGRESS")))) -> OVERDUE | H28: =IF($B28="","",$E28-$B$3) -> -9
A29: Food Safety Program | B29: * Launch Site Competition | C29: IA | D29: 46235 | E29: 46239 | F29: 0.625 | G29: =IF($B29="","",IF($E29<$B$3,"OVERDUE",IF($D29=$B$3,"STARTS TODAY",IF($E29=$B$3,"DUE TODAY","IN PROGRESS")))) -> OVERDUE | H29: =IF($B29="","",$E29-$B$3) -> -36
A30: Food Safety Program | B30: * Announce Best Performing Site | C30: IA | D30: 46254 | E30: 46264 | F30: 0.625 | G30: =IF($B30="","",IF($E30<$B$3,"OVERDUE",IF($D30=$B$3,"STARTS TODAY",IF($E30=$B$3,"DUE TODAY","IN PROGRESS")))) -> OVERDUE | H30: =IF($B30="","",$E30-$B$3) -> -11
... A79: C-SAT Survey | B79: ** Comprehensive project documentation (README.md) covering setup, build and deployment | C79: IA-MH | D79: 46249 | E79: 46280 | F79: 1 | G79: =IF($B79="","",IF($E79<$B$3,"OVERDUE",IF($D79=$B$3,"STARTS TODAY",IF($E79=$B$3,"DUE TODAY","IN PROGRESS")))) -> IN PROGRESS | H79: =IF($B79="","",$E79-$B$3) -> 5
A80: C-SAT Survey | B80: * Next Phase / Future Roadmap | C80: 0 | D80: 46260 | E80: 46275 | F80: 0 | G80: =IF($B80="","",IF($E80<$B$3,"OVERDUE",IF($D80=$B$3,"STARTS TODAY",IF($E80=$B$3,"DUE TODAY","IN PROGRESS")))) -> DUE TODAY | H80: =IF($B80="","",$E80-$B$3) -> 0
A81: C-SAT Survey | B81: ** [High Priority] Automated notifications (Email/WhatsApp) to site manager & quality supervisor on critical rating below 4/10 for immediate action during meal service | C81: IA-MH | D81: 46260 | E81: 46275 | F81: 0 | G81: =IF($B81="","",IF($E81<$B$3,"OVERDUE",IF($D81=$B$3,"STARTS TODAY",IF($E81=$B$3,"DUE TODAY","IN PROGRESS")))) -> DUE TODAY | H81: =IF($B81="","",$E81-$B$3) -> 0
A82: C-SAT Survey | B82: ** [High Priority] Multi-role user permissions (RBAC): Super Admin (all branches), Site Manager (own branch only), Quality Auditor (reports only) | C82: IA-MH | D82: 46260 | E82: 46275 | F82: 0 | G82: =IF($B82="","",IF($E82<$B$3,"OVERDUE",IF($D82=$B$3,"STARTS TODAY",IF($E82=$B$3,"DUE TODAY","IN PROGRESS")))) -> DUE TODAY | H82: =IF($B82="","",$E82-$B$3) -> 0
A83: C-SAT Survey | B83: ** [Medium Priority] Meal shift classification filter (breakfast/lunch/dinner/suhoor/dry ration) to analyze quality per work shift | C83: IA-MH | D83: 46260 | E83: 46275 | F83: 0 | G83: =IF($B83="","",IF($E83<$B$3,"OVERDUE",IF($D83=$B$3,"STARTS TODAY",IF($E83=$B$3,"DUE TODAY","IN PROGRESS")))) -> DUE TODAY | H83: =IF($B83="","",$E83-$B$3) -> 0
A84: C-SAT Survey | B84: ** [Medium Priority] Photo upload with survey complaints so workers can attach a picture of the meal/dish to document issues for central kitchen teams | C84: IA-MH | D84: 46260 | E84: 46275 | F84: 0 | G84: =IF($B84="","",IF($E84<$B$3,"OVERDUE",IF($D84=$B$3,"STARTS TODAY",IF($E84=$B$3,"DUE TODAY","IN PROGRESS")))) -> DUE TODAY | H84: =IF($B84="","",$E84-$B$3) -> 0
A85: C-SAT Survey | B85: ** [Enhancement] Scheduled executive digest: automated weekly/monthly PDF summary report emailed to Trio Catering senior management | C85: IA-MH | D85: 46260 | E85: 46275 | F85: 0 | G85: =IF($B85="","",IF($E85<$B$3,"OVERDUE",IF($D85=$B$3,"STARTS TODAY",IF($E85=$B$3,"DUE TODAY","IN PROGRESS")))) -> DUE TODAY | H85: =IF($B85="","",$E85-$B$3) -> 0
A86: C-SAT Survey | B86: ** [Enhancement] Additional language support (Arabic / English / Urdu / Hindi) in survey interface to cover expatriate workforce at factories and sites | C86: IA-MH | D86: 46260 | E86: 46275 | F86: 0 | G86: =IF($B86="","",IF($E86<$B$3,"OVERDUE",IF($D86=$B$3,"STARTS TODAY",IF($E86=$B$3,"DUE TODAY","IN PROGRESS")))) -> DUE TODAY | H86: =IF($B86="","",$E86-$B$3) -> 0
A87: GPM&I Project Plan | B87: 1 | C87: MAS & MM & IA | D87: MAS & MM & IA | E87: 46272 | F87: 0 | G87: =IF($B87="","",IF($E87<$B$3,"OVERDUE",IF($D87=$B$3,"STARTS TODAY",IF($E87=$B$3,"DUE TODAY","IN PROGRESS")))) -> OVERDUE | H87: =IF($B87="","",$E87-$B$3) -> -3
A88: Trio Academy(LMS) | B88: Create Certificate Template for Food Safety | C88: IA | D88: 46271 | E88: 46271 | F88: 0.6 | G88: =IF($B88="","",IF($E88<$B$3,"OVERDUE",IF($D88=$B$3,"STARTS TODAY",IF($E88=$B$3,"DUE TODAY","IN PROGRESS")))) -> OVERDUE | H88: =IF($B88="","",$E88-$B$3) -> -4
...

Sheet Cloud's Chatbot

Sheet C-SAT Survey
A1: C-SaT Survay Project Plan 24/08/2026 | F1: Progress | O1: STATUS SUMMARY
A2: S | B2: C-SaT Survay | C2: Resp | D2: Start Date | E2: End Date | F2: Project concept approval | G2: Project paln & approval | H2: Implementaion | O2: Done | P2: =COUNTIFS($M$4:$M$75,1) -> 57 | Q2: =IFERROR(P2/P$6,0) -> 0.87692308
H3: CEO | I3: AI | J3: IT | K3: OPS | L3: Missing | M3: Done | O3: In progress / Pending | P3: =COUNTIFS($M$4:$M$75,">0",$M$4:$M$75,"<1") -> 0 | Q3: =IFERROR(P3/P$6,0) -> 0
B4: Planning & Setup | F4: TRUE | G4: TRUE | H4: TRUE | I4: TRUE | J4: TRUE | K4: TRUE | O4: Backlog / Not started | P4: =COUNTIFS($M$4:$M$75,0) -> 8 | Q4: =IFERROR(P4/P$6,0) -> 0.12307692
A5: 1 | B5: Planning for Implementation | C5: IA-MH | D5: 46231 | E5: 46232 | F5: TRUE | G5: TRUE | H5: TRUE | I5: TRUE | J5: TRUE | K5: TRUE | L5: =IF(COUNTA(F5:K5)=0,"",1-M5) -> 0 | M5: =IF(COUNTA(F5:K5)=0,"",COUNTIF(F5:K5,TRUE)/COUNTA(F5:K5)) -> 1 | O5: Overall completion | P5: =IFERROR(AVERAGE($M$4:$M$75),0) -> 0.87692308
A6: 2 | B6: Creating Google Forms | C6: IA-MH | D6: 46232 | E6: 46232 | F6: TRUE | G6: TRUE | H6: TRUE | I6: TRUE | J6: TRUE | K6: TRUE | L6: =IF(COUNTA(F6:K6)=0,"",1-M6) -> 0 | M6: =IF(COUNTA(F6:K6)=0,"",COUNTIF(F6:K6,TRUE)/COUNTA(F6:K6)) -> 1 | O6: Total tasks | P6: =COUNT($M$4:$M$75) -> 65
A7: 3 | B7: Review | C7: IA-MH-MAS | D7: 46232 | E7: 46233 | F7: TRUE | G7: TRUE | H7: TRUE | I7: TRUE | J7: TRUE | K7: TRUE | L7: =IF(COUNTA(F7:K7)=0,"",1-M7) -> 0 | M7: =IF(COUNTA(F7:K7)=0,"",COUNTIF(F7:K7,TRUE)/COUNTA(F7:K7)) -> 1
A8: 4 | B8: Generate QR for Forms | C8: IA-MH | D8: 46232 | E8: 46233 | F8: TRUE | G8: TRUE | H8: TRUE | I8: TRUE | J8: TRUE | K8: TRUE | L8: =IF(COUNTA(F8:K8)=0,"",1-M8) -> 0 | M8: =IF(COUNTA(F8:K8)=0,"",COUNTIF(F8:K8,TRUE)/COUNTA(F8:K8)) -> 1
A9: 5 | B9: Test Forms with QR code | C9: IA-MH-MM-AM | D9: 46232 | E9: 46233 | F9: TRUE | G9: TRUE | H9: TRUE | I9: TRUE | J9: TRUE | K9: TRUE | L9: =IF(COUNTA(F9:K9)=0,"",1-M9) -> 0 | M9: =IF(COUNTA(F9:K9)=0,"",COUNTIF(F9:K9,TRUE)/COUNTA(F9:K9)) -> 1
A10: 6 | B10: Deliver QR code | C10: IA-MH | D10: 46233 | F10: TRUE | G10: TRUE | H10: TRUE | I10: TRUE | J10: TRUE | K10: TRUE | L10: =IF(COUNTA(F10:K10)=0,"",1-M10) -> 0 | M10: =IF(COUNTA(F10:K10)=0,"",COUNTIF(F10:K10,TRUE)/COUNTA(F10:K10)) -> 1
B11: Site Rollout (Client Deployments) | F11: TRUE | G11: TRUE | H11: TRUE | I11: TRUE | J11: TRUE | K11: TRUE
A12: 7 | B12: * MARS | C12: IA-MH | D12: 46234 | E12: 46249 | F12: TRUE | G12: TRUE | H12: TRUE | I12: TRUE | J12: TRUE | K12: TRUE | L12: =IF(COUNTA(F12:K12)=0,"",1-M12) -> 0 | M12: =IF(COUNTA(F12:K12)=0,"",COUNTIF(F12:K12,TRUE)/COUNTA(F12:K12)) -> 1
A13: 8 | B13: * EDITA: | C13: IA-MH | D13: 46235 | E13: 46241 | F13: TRUE | G13: TRUE | H13: TRUE | I13: TRUE | J13: TRUE | K13: TRUE | L13: =IF(COUNTA(F13:K13)=0,"",1-M13) -> 0 | M13: =IF(COUNTA(F13:K13)=0,"",COUNTIF(F13:K13,TRUE)/COUNTA(F13:K13)) -> 1
A14: 9 | B14: ** EDITA-6 | C14: IA-MH | D14: 46236 | E14: 46236 | F14: TRUE | G14: TRUE | H14: TRUE | I14: TRUE | J14: TRUE | K14: TRUE | L14: =IF(COUNTA(F14:K14)=0,"",1-M14) -> 0 | M14: =IF(COUNTA(F14:K14)=0,"",COUNTIF(F14:K14,TRUE)/COUNTA(F14:K14)) -> 1
A15: 10 | B15: ** EDITA-7 | C15: IA-MH | D15: 46237 | E15: 46237 | F15: TRUE | G15: TRUE | H15: TRUE | I15: TRUE | J15: TRUE | K15: TRUE | L15: =IF(COUNTA(F15:K15)=0,"",1-M15) -> 0 | M15: =IF(COUNTA(F15:K15)=0,"",COUNTIF(F15:K15,TRUE)/COUNTA(F15:K15)) -> 1
A16: 11 | B16: ** EDITA-8 | C16: IA-MH | D16: 46238 | E16: 46238 | F16: TRUE | G16: TRUE | H16: TRUE | I16: TRUE | J16: TRUE | K16: TRUE | L16: =IF(COUNTA(F16:K16)=0,"",1-M16) -> 0 | M16: =IF(COUNTA(F16:K16)=0,"",COUNTIF(F16:K16,TRUE)/COUNTA(F16:K16)) -> 1
A17: 12 | B17: ** EDITA-9 | C17: IA-MH | D17: 46239 | E17: 46239 | F17: TRUE | G17: TRUE | H17: TRUE | I17: TRUE | J17: TRUE | K17: TRUE | L17: =IF(COUNTA(F17:K17)=0,"",1-M17) -> 0 | M17: =IF(COUNTA(F17:K17)=0,"",COUNTIF(F17:K17,TRUE)/COUNTA(F17:K17)) -> 1
A18: 13 | B18: ** EDITA-10 | C18: IA-MH | D18: 46240 | E18: 46240 | F18: TRUE | G18: TRUE | H18: TRUE | I18: TRUE | J18: TRUE | K18: TRUE | L18: =IF(COUNTA(F18:K18)=0,"",1-M18) -> 0 | M18: =IF(COUNTA(F18:K18)=0,"",COUNTIF(F18:K18,TRUE)/COUNTA(F18:K18)) -> 1
A19: 14 | B19: ** EDITA-15 | C19: IA-MH | D19: 46241 | E19: 46241 | F19: TRUE | G19: TRUE | H19: TRUE | I19: TRUE | J19: TRUE | K19: TRUE | L19: =IF(COUNTA(F19:K19)=0,"",1-M19) -> 0 | M19: =IF(COUNTA(F19:K19)=0,"",COUNTIF(F19:K19,TRUE)/COUNTA(F19:K19)) -> 1
A20: 15 | B20: * MONDELEZ: | C20: IA-MH | D20: 46242 | E20: 46245 | F20: TRUE | G20: TRUE | H20: TRUE | I20: TRUE | J20: TRUE | K20: TRUE | L20: =IF(COUNTA(F20:K20)=0,"",1-M20) -> 0 | M20: =IF(COUNTA(F20:K20)=0,"",COUNTIF(F20:K20,TRUE)/COUNTA(F20:K20)) -> 1
A21: 16 | B21: ** MONDELEZ BEA | C21: IA-MH | D21: 46243 | E21: 46243 | F21: TRUE | G21: TRUE | H21: TRUE | I21: TRUE | J21: TRUE | K21: TRUE | L21: =IF(COUNTA(F21:K21)=0,"",1-M21) -> 0 | M21: =IF(COUNTA(F21:K21)=0,"",COUNTIF(F21:K21,TRUE)/COUNTA(F21:K21)) -> 1
A22: 17 | B22: ** MONDELEZ C-TOR | C22: IA-MH | D22: 46244 | E22: 46244 | F22: TRUE | G22: TRUE | H22: TRUE | I22: TRUE | J22: TRUE | K22: TRUE | L22: =IF(COUNTA(F22:K22)=0,"",1-M22) -> 0 | M22: =IF(COUNTA(F22:K22)=0,"",COUNTIF(F22:K22,TRUE)/COUNTA(F22:K22)) -> 1
A23: 18 | B23: ** MONDELEZ B-TOR | C23: IA-MH | D23: 46245 | E23: 46245 | F23: TRUE | G23: TRUE | H23: TRUE | I23: TRUE | J23: TRUE | K23: TRUE | L23: =IF(COUNTA(F23:K23)=0,"",1-M23) -> 0 | M23: =IF(COUNTA(F23:K23)=0,"",COUNTIF(F23:K23,TRUE)/COUNTA(F23:K23)) -> 1
